Workbook

Sheet README
A1: RACE SHED FANTASY V6 — COMMISSIONER BROADCAST SYSTEM
A3: Purpose | B3: Full-season NASCAR fantasy sheet for Pat, Meg, Darin, and Alz. Players send picks to you; you enter them.
A4: How to use | B4: 1) Enter picks in WeeklyPicks. 2) Enter finishing order in RaceResults. 3) Dashboard, RaceSummary, DriverStats, and TV_Leaderboard update automatically.
A5: Points | B5: This version aligns with the 2026 official NASCAR race-finishing table for finishing position only: winner = 55, 2nd = 35, 3rd = 34, down to 1 point for 36th-40th. Stage points are not included because this workbook tracks final finishing order only.
A6: Protection | B6: All sheets are protected. Password: raceshed. Share a view-only link so nobody but you can edit.
A7: TV Mode | B7: Use Setup!B2 to choose the race shown on TV_Leaderboard.
A8: Seeded Data | B8: COTA picks and results are preloaded based on the data you gave me.
A9: Sources | B9: 2026 schedule source: NASCAR 2026 National Series Schedules PDF. 2026 points update source: NASCAR Chase 2026 announcement.

Sheet Setup
A1: Commissioner Controls
A2: Selected Race # | B2: 5 | D2: Current Player Count | E2: 10
A3: Selected Race | B3: =INDEX(Schedule!$B$2:$B$37,$B$2) -> LAS VEGAS
A4: Password | B4: raceshed | D4: Pat
D5: Meg
A6: Note | B6: Change Setup!B2 to switch the race shown on TV_Leaderboard. | D6: Darin
D7: Alz
D8: Joe
D9: Evelyn
D10: Deric
D11: Josh
D12: Jay
D13: Ryan

Sheet PointsSystem
A1: Finish | B1: 2026 Official Race Finish Points
A2: 1 | B2: 55 | D2: Source
A3: 2 | B3: 35 | D3: 2026 points update: NASCAR announced race winners now collect 55 points; all other positions remain the same.
A4: 3 | B4: 34
A5: 4 | B5: 33 | D5: URL
A6: 5 | B6: 32 | D6: https://www.nascar.com/news-media/2026/01/12/nascar-returns-to-chase-championship-format-for-2026/
A7: 6 | B7: 31
A8: 7 | B8: 30
A9: 8 | B9: 29
A10: 9 | B10: 28
A11: 10 | B11: 27
A12: 11 | B12: 26
A13: 12 | B13: 25
A14: 13 | B14: 24
A15: 14 | B15: 23
A16: 15 | B16: 22
A17: 16 | B17: 21
A18: 17 | B18: 20
... A41: 40 | B41: 1

Sheet Schedule
A1: Race # | B1: Race | C1: Date | D1: TV | E1: Season Segment | F1: Source URL
A2: 1 | B2: DAYTONA 500 | C2: 2026-02-15 | D2: FOX | E2: Regular Season | F2: https://www.nascar.com/wp-content/uploads/sites/7/2026/02/10/2026-National-Series-Schedules-Times.pdf
A3: 2 | B3: ECHOPARK (ATLANTA) | C3: 2026-02-22 | D3: FOX | E3: Regular Season | F3: https://www.nascar.com/wp-content/uploads/sites/7/2026/02/10/2026-National-Series-Schedules-Times.pdf
A4: 3 | B4: COTA (AUSTIN) | C4: 2026-03-01 | D4: FOX | E4: Regular Season | F4: https://www.nascar.com/wp-content/uploads/sites/7/2026/02/10/2026-National-Series-Schedules-Times.pdf
A5: 4 | B5: PHOENIX | C5: 2026-03-08 | D5: FS1 | E5: Regular Season | F5: https://www.nascar.com/wp-content/uploads/sites/7/2026/02/10/2026-National-Series-Schedules-Times.pdf
A6: 5 | B6: LAS VEGAS | C6: 2026-03-15 | D6: FS1 | E6: Regular Season | F6: https://www.nascar.com/wp-content/uploads/sites/7/2026/02/10/2026-National-Series-Schedules-Times.pdf
A7: 6 | B7: DARLINGTON | C7: 2026-03-22 | D7: FS1 | E7: Regular Season | F7: https://www.nascar.com/wp-content/uploads/sites/7/2026/02/10/2026-National-Series-Schedules-Times.pdf
A8: 7 | B8: MARTINSVILLE | C8: 2026-03-29 | D8: FS1 | E8: Regular Season | F8: https://www.nascar.com/wp-content/uploads/sites/7/2026/02/10/2026-National-Series-Schedules-Times.pdf
A9: 8 | B9: BRISTOL | C9: 2026-04-12 | D9: FS1 | E9: Regular Season | F9: https://www.nascar.com/wp-content/uploads/sites/7/2026/02/10/2026-National-Series-Schedules-Times.pdf
A10: 9 | B10: KANSAS | C10: 2026-04-19 | D10: FOX | E10: Regular Season | F10: https://www.nascar.com/wp-content/uploads/sites/7/2026/02/10/2026-National-Series-Schedules-Times.pdf
A11: 10 | B11: TALLADEGA | C11: 2026-04-26 | D11: FOX | E11: Regular Season | F11: https://www.nascar.com/wp-content/uploads/sites/7/2026/02/10/2026-National-Series-Schedules-Times.pdf
A12: 11 | B12: TEXAS | C12: 2026-05-03 | D12: FS1 | E12: Regular Season | F12: https://www.nascar.com/wp-content/uploads/sites/7/2026/02/10/2026-National-Series-Schedules-Times.pdf
A13: 12 | B13: WATKINS GLEN | C13: 2026-05-10 | D13: FS1 | E13: Regular Season | F13: https://www.nascar.com/wp-content/uploads/sites/7/2026/02/10/2026-National-Series-Schedules-Times.pdf
... A37: 36 | B37: HOMESTEAD-MIAMI | C37: 2026-11-08 | D37: NBC | E37: Chase | F37: https://www.nascar.com/wp-content/uploads/sites/7/2026/02/10/2026-National-Series-Schedules-Times.pdf

Sheet WeeklyPicks
A1: Race # | B1: Race | C1: Player | D1: Pick 1 | E1: Pick 2 | F1: Pick 3 | G1: P1 Finish | H1: P2 Finish | I1: P3 Finish | J1: P1 Pts | K1: P2 Pts | L1: P3 Pts | M1: Weekly Total
A2: 1 | B2: DAYTONA 500 | C2: Pat | G2: =IF(D2="","",SUMIFS(RaceResults!$C:$C,RaceResults!$A:$A,$A2,RaceResults!$D:$D,D2)) | H2: =IF(E2="","",SUMIFS(RaceResults!$C:$C,RaceResults!$A:$A,$A2,RaceResults!$D:$D,E2)) | I2: =IF(F2="","",SUMIFS(RaceResults!$C:$C,RaceResults!$A:$A,$A2,RaceResults!$D:$D,F2)) | J2: =IF(D2="","",SUMIFS(RaceResults!$E:$E,RaceResults!$A:$A,$A2,RaceResults!$D:$D,D2)) | K2: =IF(E2="","",SUMIFS(RaceResults!$E:$E,RaceResults!$A:$A,$A2,RaceResults!$D:$D,E2)) | L2: =IF(F2="","",SUMIFS(RaceResults!$E:$E,RaceResults!$A:$A,$A2,RaceResults!$D:$D,F2)) | M2: =SUM(J2:L2) -> 0
A3: 1 | B3: DAYTONA 500 | C3: Meg | G3: =IF(D3="","",SUMIFS(RaceResults!$C:$C,RaceResults!$A:$A,$A3,RaceResults!$D:$D,D3)) | H3: =IF(E3="","",SUMIFS(RaceResults!$C:$C,RaceResults!$A:$A,$A3,RaceResults!$D:$D,E3)) | I3: =IF(F3="","",SUMIFS(RaceResults!$C:$C,RaceResults!$A:$A,$A3,RaceResults!$D:$D,F3)) | J3: =IF(D3="","",SUMIFS(RaceResults!$E:$E,RaceResults!$A:$A,$A3,RaceResults!$D:$D,D3)) | K3: =IF(E3="","",SUMIFS(RaceResults!$E:$E,RaceResults!$A:$A,$A3,RaceResults!$D:$D,E3)) | L3: =IF(F3="","",SUMIFS(RaceResults!$E:$E,RaceResults!$A:$A,$A3,RaceResults!$D:$D,F3)) | M3: =SUM(J3:L3) -> 0
A4: 1 | B4: DAYTONA 500 | C4: Darin | G4: =IF(D4="","",SUMIFS(RaceResults!$C:$C,RaceResults!$A:$A,$A4,RaceResults!$D:$D,D4)) | H4: =IF(E4="","",SUMIFS(RaceResults!$C:$C,RaceResults!$A:$A,$A4,RaceResults!$D:$D,E4)) | I4: =IF(F4="","",SUMIFS(RaceResults!$C:$C,RaceResults!$A:$A,$A4,RaceResults!$D:$D,F4)) | J4: =IF(D4="","",SUMIFS(RaceResults!$E:$E,RaceResults!$A:$A,$A4,RaceResults!$D:$D,D4)) | K4: =IF(E4="","",SUMIFS(RaceResults!$E:$E,RaceResults!$A:$A,$A4,RaceResults!$D:$D,E4)) | L4: =IF(F4="","",SUMIFS(RaceResults!$E:$E,RaceResults!$A:$A,$A4,RaceResults!$D:$D,F4)) | M4: =SUM(J4:L4) -> 0
A5: 1 | B5: DAYTONA 500 | C5: Alz | G5: =IF(D5="","",SUMIFS(RaceResults!$C:$C,RaceResults!$A:$A,$A5,RaceResults!$D:$D,D5)) | H5: =IF(E5="","",SUMIFS(RaceResults!$C:$C,RaceResults!$A:$A,$A5,RaceResults!$D:$D,E5)) | I5: =IF(F5="","",SUMIFS(RaceResults!$C:$C,RaceResults!$A:$A,$A5,RaceResults!$D:$D,F5)) | J5: =IF(D5="","",SUMIFS(RaceResults!$E:$E,RaceResults!$A:$A,$A5,RaceResults!$D:$D,D5)) | K5: =IF(E5="","",SUMIFS(RaceResults!$E:$E,RaceResults!$A:$A,$A5,RaceResults!$D:$D,E5)) | L5: =IF(F5="","",SUMIFS(RaceResults!$E:$E,RaceResults!$A:$A,$A5,RaceResults!$D:$D,F5)) | M5: =SUM(J5:L5) -> 0
A6: 1 | B6: DAYTONA 500 | C6: Joe | G6: =IF(D6="","",SUMIFS(RaceResults!$C:$C,RaceResults!$A:$A,$A6,RaceResults!$D:$D,D6)) | H6: =IF(E6="","",SUMIFS(RaceResults!$C:$C,RaceResults!$A:$A,$A6,RaceResults!$D:$D,E6)) | I6: =IF(F6="","",SUMIFS(RaceResults!$C:$C,RaceResults!$A:$A,$A6,RaceResults!$D:$D,F6)) | J6: =IF(D6="","",SUMIFS(RaceResults!$E:$E,RaceResults!$A:$A,$A6,RaceResults!$D:$D,D6)) | K6: =IF(E6="","",SUMIFS(RaceResults!$E:$E,RaceResults!$A:$A,$A6,RaceResults!$D:$D,E6)) | L6: =IF(F6="","",SUMIFS(RaceResults!$E:$E,RaceResults!$A:$A,$A6,RaceResults!$D:$D,F6)) | M6: =SUM(J6:L6) -> 0
A7: 1 | B7: DAYTONA 500 | C7: Evelyn | G7: =IF(D7="","",SUMIFS(RaceResults!$C:$C,RaceResults!$A:$A,$A7,RaceResults!$D:$D,D7)) | H7: =IF(E7="","",SUMIFS(RaceResults!$C:$C,RaceResults!$A:$A,$A7,RaceResults!$D:$D,E7)) | I7: =IF(F7="","",SUMIFS(RaceResults!$C:$C,RaceResults!$A:$A,$A7,RaceResults!$D:$D,F7)) | J7: =IF(D7="","",SUMIFS(RaceResults!$E:$E,RaceResults!$A:$A,$A7,RaceResults!$D:$D,D7)) | K7: =IF(E7="","",SUMIFS(RaceResults!$E:$E,RaceResults!$A:$A,$A7,RaceResults!$D:$D,E7)) | L7: =IF(F7="","",SUMIFS(RaceResults!$E:$E,RaceResults!$A:$A,$A7,RaceResults!$D:$D,F7)) | M7: =SUM(J7:L7) -> 0
A8: 1 | B8: DAYTONA 500 | C8: Deric | G8: =IF(D8="","",SUMIFS(RaceResults!$C:$C,RaceResults!$A:$A,$A8,RaceResults!$D:$D,D8)) | H8: =IF(E8="","",SUMIFS(RaceResults!$C:$C,RaceResults!$A:$A,$A8,RaceResults!$D:$D,E8)) | I8: =IF(F8="","",SUMIFS(RaceResults!$C:$C,RaceResults!$A:$A,$A8,RaceResults!$D:$D,F8)) | J8: =IF(D8="","",SUMIFS(RaceResults!$E:$E,RaceResults!$A:$A,$A8,RaceResults!$D:$D,D8)) | K8: =IF(E8="","",SUMIFS(RaceResults!$E:$E,RaceResults!$A:$A,$A8,RaceResults!$D:$D,E8)) | L8: =IF(F8="","",SUMIFS(RaceResults!$E:$E,RaceResults!$A:$A,$A8,RaceResults!$D:$D,F8)) | M8: =SUM(J8:L8) -> 0
A9: 1 | B9: DAYTONA 500 | C9: Josh | G9: =IF(D9="","",SUMIFS(RaceResults!$C:$C,RaceResults!$A:$A,$A9,RaceResults!$D:$D,D9)) | H9: =IF(E9="","",SUMIFS(RaceResults!$C:$C,RaceResults!$A:$A,$A9,RaceResults!$D:$D,E9)) | I9: =IF(F9="","",SUMIFS(RaceResults!$C:$C,RaceResults!$A:$A,$A9,RaceResults!$D:$D,F9)) | J9: =IF(D9="","",SUMIFS(RaceResults!$E:$E,RaceResults!$A:$A,$A9,RaceResults!$D:$D,D9)) | K9: =IF(E9="","",SUMIFS(RaceResults!$E:$E,RaceResults!$A:$A,$A9,RaceResults!$D:$D,E9)) | L9: =IF(F9="","",SUMIFS(RaceResults!$E:$E,RaceResults!$A:$A,$A9,RaceResults!$D:$D,F9)) | M9: =SUM(J9:L9) -> 0
A10: 1 | B10: DAYTONA 500 | C10: Jay | G10: =IF(D10="","",SUMIFS(RaceResults!$C:$C,RaceResults!$A:$A,$A10,RaceResults!$D:$D,D10)) | H10: =IF(E10="","",SUMIFS(RaceResults!$C:$C,RaceResults!$A:$A,$A10,RaceResults!$D:$D,E10)) | I10: =IF(F10="","",SUMIFS(RaceResults!$C:$C,RaceResults!$A:$A,$A10,RaceResults!$D:$D,F10)) | J10: =IF(D10="","",SUMIFS(RaceResults!$E:$E,RaceResults!$A:$A,$A10,RaceResults!$D:$D,D10)) | K10: =IF(E10="","",SUMIFS(RaceResults!$E:$E,RaceResults!$A:$A,$A10,RaceResults!$D:$D,E10)) | L10: =IF(F10="","",SUMIFS(RaceResults!$E:$E,RaceResults!$A:$A,$A10,RaceResults!$D:$D,F10)) | M10: =SUM(J10:L10) -> 0
A11: 1 | B11: DAYTONA 500 | C11: Ryan | G11: =IF(D11="","",SUMIFS(RaceResults!$C:$C,RaceResults!$A:$A,$A11,RaceResults!$D:$D,D11)) | H11: =IF(E11="","",SUMIFS(RaceResults!$C:$C,RaceResults!$A:$A,$A11,RaceResults!$D:$D,E11)) | I11: =IF(F11="","",SUMIFS(RaceResults!$C:$C,RaceResults!$A:$A,$A11,RaceResults!$D:$D,F11)) | J11: =IF(D11="","",SUMIFS(RaceResults!$E:$E,RaceResults!$A:$A,$A11,RaceResults!$D:$D,D11)) | K11: =IF(E11="","",SUMIFS(RaceResults!$E:$E,RaceResults!$A:$A,$A11,RaceResults!$D:$D,E11)) | L11: =IF(F11="","",SUMIFS(RaceResults!$E:$E,RaceResults!$A:$A,$A11,RaceResults!$D:$D,F11)) | M11: =SUM(J11:L11) -> 0
A12: 2 | B12: ECHOPARK (ATLANTA) | C12: Pat | G12: =IF(D12="","",SUMIFS(RaceResults!$C:$C,RaceResults!$A:$A,$A12,RaceResults!$D:$D,D12)) | H12: =IF(E12="","",SUMIFS(RaceResults!$C:$C,RaceResults!$A:$A,$A12,RaceResults!$D:$D,E12)) | I12: =IF(F12="","",SUMIFS(RaceResults!$C:$C,RaceResults!$A:$A,$A12,RaceResults!$D:$D,F12)) | J12: =IF(D12="","",SUMIFS(RaceResults!$E:$E,RaceResults!$A:$A,$A12,RaceResults!$D:$D,D12)) | K12: =IF(E12="","",SUMIFS(RaceResults!$E:$E,RaceResults!$A:$A,$A12,RaceResults!$D:$D,E12)) | L12: =IF(F12="","",SUMIFS(RaceResults!$E:$E,RaceResults!$A:$A,$A12,RaceResults!$D:$D,F12)) | M12: =SUM(J12:L12) -> 0
A13: 2 | B13: ECHOPARK (ATLANTA) | C13: Meg | G13: =IF(D13="","",SUMIFS(RaceResults!$C:$C,RaceResults!$A:$A,$A13,RaceResults!$D:$D,D13)) | H13: =IF(E13="","",SUMIFS(RaceResults!$C:$C,RaceResults!$A:$A,$A13,RaceResults!$D:$D,E13)) | I13: =IF(F13="","",SUMIFS(RaceResults!$C:$C,RaceResults!$A:$A,$A13,RaceResults!$D:$D,F13)) | J13: =IF(D13="","",SUMIFS(RaceResults!$E:$E,RaceResults!$A:$A,$A13,RaceResults!$D:$D,D13)) | K13: =IF(E13="","",SUMIFS(RaceResults!$E:$E,RaceResults!$A:$A,$A13,RaceResults!$D:$D,E13)) | L13: =IF(F13="","",SUMIFS(RaceResults!$E:$E,RaceResults!$A:$A,$A13,RaceResults!$D:$D,F13)) | M13: =SUM(J13:L13) -> 0
... A21: 2 | B21: ECHOPARK (ATLANTA) | C21: Ryan | G21: =IF(D21="","",SUMIFS(RaceResults!$C:$C,RaceResults!$A:$A,$A21,RaceResults!$D:$D,D21)) | H21: =IF(E21="","",SUMIFS(RaceResults!$C:$C,RaceResults!$A:$A,$A21,RaceResults!$D:$D,E21)) | I21: =IF(F21="","",SUMIFS(RaceResults!$C:$C,RaceResults!$A:$A,$A21,RaceResults!$D:$D,F21)) | J21: =IF(D21="","",SUMIFS(RaceResults!$E:$E,RaceResults!$A:$A,$A21,RaceResults!$D:$D,D21)) | K21: =IF(E21="","",SUMIFS(RaceResults!$E:$E,RaceResults!$A:$A,$A21,RaceResults!$D:$D,E21)) | L21: =IF(F21="","",SUMIFS(RaceResults!$E:$E,RaceResults!$A:$A,$A21,RaceResults!$D:$D,F21)) | M21: =SUM(J21:L21) -> 0
A22: 3 | B22: COTA (AUSTIN) | C22: Pat | D22: 97 | E22: 20 | F22: 9 | G22: =IF(D22="","",SUMIFS(RaceResults!$C:$C,RaceResults!$A:$A,$A22,RaceResults!$D:$D,D22)) -> 2 | H22: =IF(E22="","",SUMIFS(RaceResults!$C:$C,RaceResults!$A:$A,$A22,RaceResults!$D:$D,E22)) -> 3 | I22: =IF(F22="","",SUMIFS(RaceResults!$C:$C,RaceResults!$A:$A,$A22,RaceResults!$D:$D,F22)) -> 7 | J22: =IF(D22="","",SUMIFS(RaceResults!$E:$E,RaceResults!$A:$A,$A22,RaceResults!$D:$D,D22)) -> 35 | K22: =IF(E22="","",SUMIFS(RaceResults!$E:$E,RaceResults!$A:$A,$A22,RaceResults!$D:$D,E22)) -> 34 | L22: =IF(F22="","",SUMIFS(RaceResults!$E:$E,RaceResults!$A:$A,$A22,RaceResults!$D:$D,F22)) -> 30 | M22: =SUM(J22:L22) -> 99
A23: 3 | B23: COTA (AUSTIN) | C23: Meg | D23: 45 | E23: 12 | F23: 11 | G23: =IF(D23="","",SUMIFS(RaceResults!$C:$C,RaceResults!$A:$A,$A23,RaceResults!$D:$D,D23)) -> 1 | H23: =IF(E23="","",SUMIFS(RaceResults!$C:$C,RaceResults!$A:$A,$A23,RaceResults!$D:$D,E23)) -> 8 | I23: =IF(F23="","",SUMIFS(RaceResults!$C:$C,RaceResults!$A:$A,$A23,RaceResults!$D:$D,F23)) -> 10 | J23: =IF(D23="","",SUMIFS(RaceResults!$E:$E,RaceResults!$A:$A,$A23,RaceResults!$D:$D,D23)) -> 55 | K23: =IF(E23="","",SUMIFS(RaceResults!$E:$E,RaceResults!$A:$A,$A23,RaceResults!$D:$D,E23)) -> 29 | L23: =IF(F23="","",SUMIFS(RaceResults!$E:$E,RaceResults!$A:$A,$A23,RaceResults!$D:$D,F23)) -> 27 | M23: =SUM(J23:L23) -> 111
A24: 3 | B24: COTA (AUSTIN) | C24: Darin | D24: 19 | E24: 20 | F24: 24 | G24: =IF(D24="","",SUMIFS(RaceResults!$C:$C,RaceResults!$A:$A,$A24,RaceResults!$D:$D,D24)) -> 37 | H24: =IF(E24="","",SUMIFS(RaceResults!$C:$C,RaceResults!$A:$A,$A24,RaceResults!$D:$D,E24)) -> 3 | I24: =IF(F24="","",SUMIFS(RaceResults!$C:$C,RaceResults!$A:$A,$A24,RaceResults!$D:$D,F24)) -> 13 | J24: =IF(D24="","",SUMIFS(RaceResults!$E:$E,RaceResults!$A:$A,$A24,RaceResults!$D:$D,D24)) -> 1 | K24: =IF(E24="","",SUMIFS(RaceResults!$E:$E,RaceResults!$A:$A,$A24,RaceResults!$D:$D,E24)) -> 34 | L24: =IF(F24="","",SUMIFS(RaceResults!$E:$E,RaceResults!$A:$A,$A24,RaceResults!$D:$D,F24)) -> 24 | M24: =SUM(J24:L24) -> 59
A25: 3 | B25: COTA (AUSTIN) | C25: Alz | D25: 97 | E25: 19 | F25: 11 | G25: =IF(D25="","",SUMIFS(RaceResults!$C:$C,RaceResults!$A:$A,$A25,RaceResults!$D:$D,D25)) -> 2 | H25: =IF(E25="","",SUMIFS(RaceResults!$C:$C,RaceResults!$A:$A,$A25,RaceResults!$D:$D,E25)) -> 37 | I25: =IF(F25="","",SUMIFS(RaceResults!$C:$C,RaceResults!$A:$A,$A25,RaceResults!$D:$D,F25)) -> 10 | J25: =IF(D25="","",SUMIFS(RaceResults!$E:$E,RaceResults!$A:$A,$A25,RaceResults!$D:$D,D25)) -> 35 | K25: =IF(E25="","",SUMIFS(RaceResults!$E:$E,RaceResults!$A:$A,$A25,RaceResults!$D:$D,E25)) -> 1 | L25: =IF(F25="","",SUMIFS(RaceResults!$E:$E,RaceResults!$A:$A,$A25,RaceResults!$D:$D,F25)) -> 27 | M25: =SUM(J25:L25) -> 63
A26: 3 | B26: COTA (AUSTIN) | C26: Joe | G26: =IF(D26="","",SUMIFS(RaceResults!$C:$C,RaceResults!$A:$A,$A26,RaceResults!$D:$D,D26)) | H26: =IF(E26="","",SUMIFS(RaceResults!$C:$C,RaceResults!$A:$A,$A26,RaceResults!$D:$D,E26)) | I26: =IF(F26="","",SUMIFS(RaceResults!$C:$C,RaceResults!$A:$A,$A26,RaceResults!$D:$D,F26)) | J26: =IF(D26="","",SUMIFS(RaceResults!$E:$E,RaceResults!$A:$A,$A26,RaceResults!$D:$D,D26)) | K26: =IF(E26="","",SUMIFS(RaceResults!$E:$E,RaceResults!$A:$A,$A26,RaceResults!$D:$D,E26)) | L26: =IF(F26="","",SUMIFS(RaceResults!$E:$E,RaceResults!$A:$A,$A26,RaceResults!$D:$D,F26)) | M26: =SUM(J26:L26) -> 0
A27: 3 | B27: COTA (AUSTIN) | C27: Evelyn | G27: =IF(D27="","",SUMIFS(RaceResults!$C:$C,RaceResults!$A:$A,$A27,RaceResults!$D:$D,D27)) | H27: =IF(E27="","",SUMIFS(RaceResults!$C:$C,RaceResults!$A:$A,$A27,RaceResults!$D:$D,E27)) | I27: =IF(F27="","",SUMIFS(RaceResults!$C:$C,RaceResults!$A:$A,$A27,RaceResults!$D:$D,F27)) | J27: =IF(D27="","",SUMIFS(RaceResults!$E:$E,RaceResults!$A:$A,$A27,RaceResults!$D:$D,D27)) | K27: =IF(E27="","",SUMIFS(RaceResults!$E:$E,RaceResults!$A:$A,$A27,RaceResults!$D:$D,E27)) | L27: =IF(F27="","",SUMIFS(RaceResults!$E:$E,RaceResults!$A:$A,$A27,RaceResults!$D:$D,F27)) | M27: =SUM(J27:L27) -> 0
A28: 3 | B28: COTA (AUSTIN) | C28: Deric | G28: =IF(D28="","",SUMIFS(RaceResults!$C:$C,RaceResults!$A:$A,$A28,RaceResults!$D:$D,D28)) | H28: =IF(E28="","",SUMIFS(RaceResults!$C:$C,RaceResults!$A:$A,$A28,RaceResults!$D:$D,E28)) | I28: =IF(F28="","",SUMIFS(RaceResults!$C:$C,RaceResults!$A:$A,$A28,RaceResults!$D:$D,F28)) | J28: =IF(D28="","",SUMIFS(RaceResults!$E:$E,RaceResults!$A:$A,$A28,RaceResults!$D:$D,D28)) | K28: =IF(E28="","",SUMIFS(RaceResults!$E:$E,RaceResults!$A:$A,$A28,RaceResults!$D:$D,E28)) | L28: =IF(F28="","",SUMIFS(RaceResults!$E:$E,RaceResults!$A:$A,$A28,RaceResults!$D:$D,F28)) | M28: =SUM(J28:L28) -> 0
A29: 3 | B29: COTA (AUSTIN) | C29: Josh | G29: =IF(D29="","",SUMIFS(RaceResults!$C:$C,RaceResults!$A:$A,$A29,RaceResults!$D:$D,D29)) | H29: =IF(E29="","",SUMIFS(RaceResults!$C:$C,RaceResults!$A:$A,$A29,RaceResults!$D:$D,E29)) | I29: =IF(F29="","",SUMIFS(RaceResults!$C:$C,RaceResults!$A:$A,$A29,RaceResults!$D:$D,F29)) | J29: =IF(D29="","",SUMIFS(RaceResults!$E:$E,RaceResults!$A:$A,$A29,RaceResults!$D:$D,D29)) | K29: =IF(E29="","",SUMIFS(RaceResults!$E:$E,RaceResults!$A:$A,$A29,RaceResults!$D:$D,E29)) | L29: =IF(F29="","",SUMIFS(RaceResults!$E:$E,RaceResults!$A:$A,$A29,RaceResults!$D:$D,F29)) | M29: =SUM(J29:L29) -> 0
A30: 3 | B30: COTA (AUSTIN) | C30: Jay | G30: =IF(D30="","",SUMIFS(RaceResults!$C:$C,RaceResults!$A:$A,$A30,RaceResults!$D:$D,D30)) | H30: =IF(E30="","",SUMIFS(RaceResults!$C:$C,RaceResults!$A:$A,$A30,RaceResults!$D:$D,E30)) | I30: =IF(F30="","",SUMIFS(RaceResults!$C:$C,RaceResults!$A:$A,$A30,RaceResults!$D:$D,F30)) | J30: =IF(D30="","",SUMIFS(RaceResults!$E:$E,RaceResults!$A:$A,$A30,RaceResults!$D:$D,D30)) | K30: =IF(E30="","",SUMIFS(RaceResults!$E:$E,RaceResults!$A:$A,$A30,RaceResults!$D:$D,E30)) | L30: =IF(F30="","",SUMIFS(RaceResults!$E:$E,RaceResults!$A:$A,$A30,RaceResults!$D:$D,F30)) | M30: =SUM(J30:L30) -> 0
A31: 3 | B31: COTA (AUSTIN) | C31: Ryan | G31: =IF(D31="","",SUMIFS(RaceResults!$C:$C,RaceResults!$A:$A,$A31,RaceResults!$D:$D,D31)) | H31: =IF(E31="","",SUMIFS(RaceResults!$C:$C,RaceResults!$A:$A,$A31,RaceResults!$D:$D,E31)) | I31: =IF(F31="","",SUMIFS(RaceResults!$C:$C,RaceResults!$A:$A,$A31,RaceResults!$D:$D,F31)) | J31: =IF(D31="","",SUMIFS(RaceResults!$E:$E,RaceResults!$A:$A,$A31,RaceResults!$D:$D,D31)) | K31: =IF(E31="","",SUMIFS(RaceResults!$E:$E,RaceResults!$A:$A,$A31,RaceResults!$D:$D,E31)) | L31: =IF(F31="","",SUMIFS(RaceResults!$E:$E,RaceResults!$A:$A,$A31,RaceResults!$D:$D,F31)) | M31: =SUM(J31:L31) -> 0
A32: 4 | B32: PHOENIX | C32: Pat | D32: 5 | E32: 11 | F32: 45 | G32: =IF(D32="","",SUMIFS(RaceResults!$C:$C,RaceResults!$A:$A,$A32,RaceResults!$D:$D,D32)) -> 3 | H32: =IF(E32="","",SUMIFS(RaceResults!$C:$C,RaceResults!$A:$A,$A32,RaceResults!$D:$D,E32)) -> 5 | I32: =IF(F32="","",SUMIFS(RaceResults!$C:$C,RaceResults!$A:$A,$A32,RaceResults!$D:$D,F32)) -> 8 | J32: =IF(D32="","",SUMIFS(RaceResults!$E:$E,RaceResults!$A:$A,$A32,RaceResults!$D:$D,D32)) -> 34 | K32: =IF(E32="","",SUMIFS(RaceResults!$E:$E,RaceResults!$A:$A,$A32,RaceResults!$D:$D,E32)) -> 32 | L32: =IF(F32="","",SUMIFS(RaceResults!$E:$E,RaceResults!$A:$A,$A32,RaceResults!$D:$D,F32)) -> 29 | M32: =SUM(J32:L32) -> 95
A33: 4 | B33: PHOENIX | C33: Meg | D33: 7 | E33: 12 | F33: 1 | G33: =IF(D33="","",SUMIFS(RaceResults!$C:$C,RaceResults!$A:$A,$A33,RaceResults!$D:$D,D33)) -> 30 | H33: =IF(E33="","",SUMIFS(RaceResults!$C:$C,RaceResults!$A:$A,$A33,RaceResults!$D:$D,E33)) -> 1 | I33: =IF(F33="","",SUMIFS(RaceResults!$C:$C,RaceResults!$A:$A,$A33,RaceResults!$D:$D,F33)) -> 28 | J33: =IF(D33="","",SUMIFS(RaceResults!$E:$E,RaceResults!$A:$A,$A33,RaceResults!$D:$D,D33)) -> 7 | K33: =IF(E33="","",SUMIFS(RaceResults!$E:$E,RaceResults!$A:$A,$A33,RaceResults!$D:$D,E33)) -> 55 | L33: =IF(F33="","",SUMIFS(RaceResults!$E:$E,RaceResults!$A:$A,$A33,RaceResults!$D:$D,F33)) -> 9 | M33: =SUM(J33:L33) -> 71
A34: 4 | B34: PHOENIX | C34: Darin | D34: 21 | E34: 22 | F34: 24 | G34: =IF(D34="","",SUMIFS(RaceResults!$C:$C,RaceResults!$A:$A,$A34,RaceResults!$D:$D,D34)) -> 32 | H34: =IF(E34="","",SUMIFS(RaceResults!$C:$C,RaceResults!$A:$A,$A34,RaceResults!$D:$D,E34)) -> 31 | I34: =IF(F34="","",SUMIFS(RaceResults!$C:$C,RaceResults!$A:$A,$A34,RaceResults!$D:$D,F34)) -> 7 | J34: =IF(D34="","",SUMIFS(RaceResults!$E:$E,RaceResults!$A:$A,$A34,RaceResults!$D:$D,D34)) -> 5 | K34: =IF(E34="","",SUMIFS(RaceResults!$E:$E,RaceResults!$A:$A,$A34,RaceResults!$D:$D,E34)) -> 6 | L34: =IF(F34="","",SUMIFS(RaceResults!$E:$E,RaceResults!$A:$A,$A34,RaceResults!$D:$D,F34)) -> 30 | M34: =SUM(J34:L34) -> 41
A35: 4 | B35: PHOENIX | C35: Alz | D35: 5 | E35: 12 | F35: 2 | G35: =IF(D35="","",SUMIFS(RaceResults!$C:$C,RaceResults!$A:$A,$A35,RaceResults!$D:$D,D35)) -> 3 | H35: =IF(E35="","",SUMIFS(RaceResults!$C:$C,RaceResults!$A:$A,$A35,RaceResults!$D:$D,E35)) -> 1 | I35: =IF(F35="","",SUMIFS(RaceResults!$C:$C,RaceResults!$A:$A,$A35,RaceResults!$D:$D,F35)) -> 34 | J35: =IF(D35="","",SUMIFS(RaceResults!$E:$E,RaceResults!$A:$A,$A35,RaceResults!$D:$D,D35)) -> 34 | K35: =IF(E35="","",SUMIFS(RaceResults!$E:$E,RaceResults!$A:$A,$A35,RaceResults!$D:$D,E35)) -> 55 | L35: =IF(F35="","",SUMIFS(RaceResults!$E:$E,RaceResults!$A:$A,$A35,RaceResults!$D:$D,F35)) -> 3 | M35: =SUM(J35:L35) -> 92
A36: 4 | B36: PHOENIX | C36: Joe | D36: 45 | E36: 12 | F36: 19 | G36: =IF(D36="","",SUMIFS(RaceResults!$C:$C,RaceResults!$A:$A,$A36,RaceResults!$D:$D,D36)) -> 8 | H36: =IF(E36="","",SUMIFS(RaceResults!$C:$C,RaceResults!$A:$A,$A36,RaceResults!$D:$D,E36)) -> 1 | I36: =IF(F36="","",SUMIFS(RaceResults!$C:$C,RaceResults!$A:$A,$A36,RaceResults!$D:$D,F36)) -> 37 | J36: =IF(D36="","",SUMIFS(RaceResults!$E:$E,RaceResults!$A:$A,$A36,RaceResults!$D:$D,D36)) -> 29 | K36: =IF(E36="","",SUMIFS(RaceResults!$E:$E,RaceResults!$A:$A,$A36,RaceResults!$D:$D,E36)) -> 55 | L36: =IF(F36="","",SUMIFS(RaceResults!$E:$E,RaceResults!$A:$A,$A36,RaceResults!$D:$D,F36)) -> 1 | M36: =SUM(J36:L36) -> 85
A37: 4 | B37: PHOENIX | C37: Evelyn | G37: =IF(D37="","",SUMIFS(RaceResults!$C:$C,RaceResults!$A:$A,$A37,RaceResults!$D:$D,D37)) | H37: =IF(E37="","",SUMIFS(RaceResults!$C:$C,RaceResults!$A:$A,$A37,RaceResults!$D:$D,E37)) | I37: =IF(F37="","",SUMIFS(RaceResults!$C:$C,RaceResults!$A:$A,$A37,RaceResults!$D:$D,F37)) | J37: =IF(D37="","",SUMIFS(RaceResults!$E:$E,RaceResults!$A:$A,$A37,RaceResults!$D:$D,D37)) | K37: =IF(E37="","",SUMIFS(RaceResults!$E:$E,RaceResults!$A:$A,$A37,RaceResults!$D:$D,E37)) | L37: =IF(F37="","",SUMIFS(RaceResults!$E:$E,RaceResults!$A:$A,$A37,RaceResults!$D:$D,F37)) | M37: =SUM(J37:L37) -> 0
A38: 4 | B38: PHOENIX | C38: Deric | G38: =IF(D38="","",SUMIFS(RaceResults!$C:$C,RaceResults!$A:$A,$A38,RaceResults!$D:$D,D38)) | H38: =IF(E38="","",SUMIFS(RaceResults!$C:$C,RaceResults!$A:$A,$A38,RaceResults!$D:$D,E38)) | I38: =IF(F38="","",SUMIFS(RaceResults!$C:$C,RaceResults!$A:$A,$A38,RaceResults!$D:$D,F38)) | J38: =IF(D38="","",SUMIFS(RaceResults!$E:$E,RaceResults!$A:$A,$A38,RaceResults!$D:$D,D38)) | K38: =IF(E38="","",SUMIFS(RaceResults!$E:$E,RaceResults!$A:$A,$A38,RaceResults!$D:$D,E38)) | L38: =IF(F38="","",SUMIFS(RaceResults!$E:$E,RaceResults!$A:$A,$A38,RaceResults!$D:$D,F38)) | M38: =SUM(J38:L38) -> 0
A39: 4 | B39: PHOENIX | C39: Josh | G39: =IF(D39="","",SUMIFS(RaceResults!$C:$C,RaceResults!$A:$A,$A39,RaceResults!$D:$D,D39)) | H39: =IF(E39="","",SUMIFS(RaceResults!$C:$C,RaceResults!$A:$A,$A39,RaceResults!$D:$D,E39)) | I39: =IF(F39="","",SUMIFS(RaceResults!$C:$C,RaceResults!$A:$A,$A39,RaceResults!$D:$D,F39)) | J39: =IF(D39="","",SUMIFS(RaceResults!$E:$E,RaceResults!$A:$A,$A39,RaceResults!$D:$D,D39)) | K39: =IF(E39="","",SUMIFS(RaceResults!$E:$E,RaceResults!$A:$A,$A39,RaceResults!$D:$D,E39)) | L39: =IF(F39="","",SUMIFS(RaceResults!$E:$E,RaceResults!$A:$A,$A39,RaceResults!$D:$D,F39)) | M39: =SUM(J39:L39) -> 0
A40: 4 | B40: PHOENIX | C40: Jay | G40: =IF(D40="","",SUMIFS(RaceResults!$C:$C,RaceResults!$A:$A,$A40,RaceResults!$D:$D,D40)) | H40: =IF(E40="","",SUMIFS(RaceResults!$C:$C,RaceResults!$A:$A,$A40,RaceResults!$D:$D,E40)) | I40: =IF(F40="","",SUMIFS(RaceResults!$C:$C,RaceResults!$A:$A,$A40,RaceResults!$D:$D,F40)) | J40: =IF(D40="","",SUMIFS(RaceResults!$E:$E,RaceResults!$A:$A,$A40,RaceResults!$D:$D,D40)) | K40: =IF(E40="","",SUMIFS(RaceResults!$E:$E,RaceResults!$A:$A,$A40,RaceResults!$D:$D,E40)) | L40: =IF(F40="","",SUMIFS(RaceResults!$E:$E,RaceResults!$A:$A,$A40,RaceResults!$D:$D,F40)) | M40: =SUM(J40:L40) -> 0
A41: 4 | B41: PHOENIX | C41: Ryan | G41: =IF(D41="","",SUMIFS(RaceResults!$C:$C,RaceResults!$A:$A,$A41,RaceResults!$D:$D,D41)) | H41: =IF(E41="","",SUMIFS(RaceResults!$C:$C,RaceResults!$A:$A,$A41,RaceResults!$D:$D,E41)) | I41: =IF(F41="","",SUMIFS(RaceResults!$C:$C,RaceResults!$A:$A,$A41,RaceResults!$D:$D,F41)) | J41: =IF(D41="","",SUMIFS(RaceResults!$E:$E,RaceResults!$A:$A,$A41,RaceResults!$D:$D,D41)) | K41: =IF(E41="","",SUMIFS(RaceResults!$E:$E,RaceResults!$A:$A,$A41,RaceResults!$D:$D,E41)) | L41: =IF(F41="","",SUMIFS(RaceResults!$E:$E,RaceResults!$A:$A,$A41,RaceResults!$D:$D,F41)) | M41: =SUM(J41:L41) -> 0
A42: 5 | B42: LAS VEGAS | C42: Pat | D42: 5 | E42: 45 | F42: 23 | G42: =IF(D42="","",SUMIFS(RaceResults!$C:$C,RaceResults!$A:$A,$A42,RaceResults!$D:$D,D42)) -> 7 | H42: =IF(E42="","",SUMIFS(RaceResults!$C:$C,RaceResults!$A:$A,$A42,RaceResults!$D:$D,E42)) -> 13 | I42: =IF(F42="","",SUMIFS(RaceResults!$C:$C,RaceResults!$A:$A,$A42,RaceResults!$D:$D,F42)) -> 9 | J42: =IF(D42="","",SUMIFS(RaceResults!$E:$E,RaceResults!$A:$A,$A42,RaceResults!$D:$D,D42)) -> 30 | K42: =IF(E42="","",SUMIFS(RaceResults!$E:$E,RaceResults!$A:$A,$A42,RaceResults!$D:$D,E42)) -> 24 | L42: =IF(F42="","",SUMIFS(RaceResults!$E:$E,RaceResults!$A:$A,$A42,RaceResults!$D:$D,F42)) -> 28 | M42: =SUM(J42:L42) -> 82
A43: 5 | B43: LAS VEGAS | C43: Meg | D43: 11 | E43: 12 | F43: 9 | G43: =IF(D43="","",SUMIFS(RaceResults!$C:$C,RaceResults!$A:$A,$A43,RaceResults!$D:$D,D43)) -> 1 | H43: =IF(E43="","",SUMIFS(RaceResults!$C:$C,RaceResults!$A:$A,$A43,RaceResults!$D:$D,E43)) -> 16 | I43: =IF(F43="","",SUMIFS(RaceResults!$C:$C,RaceResults!$A:$A,$A43,RaceResults!$D:$D,F43)) -> 2 | J43: =IF(D43="","",SUMIFS(RaceResults!$E:$E,RaceResults!$A:$A,$A43,RaceResults!$D:$D,D43)) -> 55 | K43: =IF(E43="","",SUMIFS(RaceResults!$E:$E,RaceResults!$A:$A,$A43,RaceResults!$D:$D,E43)) -> 21 | L43: =IF(F43="","",SUMIFS(RaceResults!$E:$E,RaceResults!$A:$A,$A43,RaceResults!$D:$D,F43)) -> 35 | M43: =SUM(J43:L43) -> 111
A44: 5 | B44: LAS VEGAS | C44: Darin | D44: 20 | E44: 23 | F44: 24 | G44: =IF(D44="","",SUMIFS(RaceResults!$C:$C,RaceResults!$A:$A,$A44,RaceResults!$D:$D,D44)) -> 4 | H44: =IF(E44="","",SUMIFS(RaceResults!$C:$C,RaceResults!$A:$A,$A44,RaceResults!$D:$D,E44)) -> 9 | I44: =IF(F44="","",SUMIFS(RaceResults!$C:$C,RaceResults!$A:$A,$A44,RaceResults!$D:$D,F44)) -> 3 | J44: =IF(D44="","",SUMIFS(RaceResults!$E:$E,RaceResults!$A:$A,$A44,RaceResults!$D:$D,D44)) -> 33 | K44: =IF(E44="","",SUMIFS(RaceResults!$E:$E,RaceResults!$A:$A,$A44,RaceResults!$D:$D,E44)) -> 28 | L44: =IF(F44="","",SUMIFS(RaceResults!$E:$E,RaceResults!$A:$A,$A44,RaceResults!$D:$D,F44)) -> 34 | M44: =SUM(J44:L44) -> 95
A45: 5 | B45: LAS VEGAS | C45: Alz | D45: 11 | E45: 12 | F45: 5 | G45: =IF(D45="","",SUMIFS(RaceResults!$C:$C,RaceResults!$A:$A,$A45,RaceResults!$D:$D,D45)) -> 1 | H45: =IF(E45="","",SUMIFS(RaceResults!$C:$C,RaceResults!$A:$A,$A45,RaceResults!$D:$D,E45)) -> 16 | I45: =IF(F45="","",SUMIFS(RaceResults!$C:$C,RaceResults!$A:$A,$A45,RaceResults!$D:$D,F45)) -> 7 | J45: =IF(D45="","",SUMIFS(RaceResults!$E:$E,RaceResults!$A:$A,$A45,RaceResults!$D:$D,D45)) -> 55 | K45: =IF(E45="","",SUMIFS(RaceResults!$E:$E,RaceResults!$A:$A,$A45,RaceResults!$D:$D,E45)) -> 21 | L45: =IF(F45="","",SUMIFS(RaceResults!$E:$E,RaceResults!$A:$A,$A45,RaceResults!$D:$D,F45)) -> 30 | M45: =SUM(J45:L45) -> 106
A46: 5 | B46: LAS VEGAS | C46: Joe | D46: 5 | E46: 11 | F46: 20 | G46: =IF(D46="","",SUMIFS(RaceResults!$C:$C,RaceResults!$A:$A,$A46,RaceResults!$D:$D,D46)) -> 7 | H46: =IF(E46="","",SUMIFS(RaceResults!$C:$C,RaceResults!$A:$A,$A46,RaceResults!$D:$D,E46)) -> 1 | I46: =IF(F46="","",SUMIFS(RaceResults!$C:$C,RaceResults!$A:$A,$A46,RaceResults!$D:$D,F46)) -> 4 | J46: =IF(D46="","",SUMIFS(RaceResults!$E:$E,RaceResults!$A:$A,$A46,RaceResults!$D:$D,D46)) -> 30 | K46: =IF(E46="","",SUMIFS(RaceResults!$E:$E,RaceResults!$A:$A,$A46,RaceResults!$D:$D,E46)) -> 55 | L46: =IF(F46="","",SUMIFS(RaceResults!$E:$E,RaceResults!$A:$A,$A46,RaceResults!$D:$D,F46)) -> 33 | M46: =SUM(J46:L46) -> 118
A47: 5 | B47: LAS VEGAS | C47: Evelyn | D47: 20 | E47: 45 | F47: 11 | G47: =IF(D47="","",SUMIFS(RaceResults!$C:$C,RaceResults!$A:$A,$A47,RaceResults!$D:$D,D47)) -> 4 | H47: =IF(E47="","",SUMIFS(RaceResults!$C:$C,RaceResults!$A:$A,$A47,RaceResults!$D:$D,E47)) -> 13 | I47: =IF(F47="","",SUMIFS(RaceResults!$C:$C,RaceResults!$A:$A,$A47,RaceResults!$D:$D,F47)) -> 1 | J47: =IF(D47="","",SUMIFS(RaceResults!$E:$E,RaceResults!$A:$A,$A47,RaceResults!$D:$D,D47)) -> 33 | K47: =IF(E47="","",SUMIFS(RaceResults!$E:$E,RaceResults!$A:$A,$A47,RaceResults!$D:$D,E47)) -> 24 | L47: =IF(F47="","",SUMIFS(RaceResults!$E:$E,RaceResults!$A:$A,$A47,RaceResults!$D:$D,F47)) -> 55 | M47: =SUM(J47:L47) -> 112
...

Sheet RaceSummary
A1: Race # | B1: Race | C1: Winner | D1: Winner Pts | E1: Most Popular Pick | F1: Pick Count | G1: Worst Pick Car | H1: Worst Finish | I1: Worst Picked By
A2: 1 | B2: DAYTONA 500 | C2: =IF(MAX(WeeklyPicks!$M$2:$M$11)=0,"",INDEX(WeeklyPicks!$C$2:$C$11,MATCH(MAX(WeeklyPicks!$M$2:$M$11),WeeklyPicks!$M$2:$M$11,0))) | D2: =MAX(WeeklyPicks!$M$2:$M$11) -> 0 | E2: =IF(MAX(CountCalc!$D$2:$D$100)=0,"",INDEX(CountCalc!$C$2:$C$100,MATCH(MAX(CountCalc!$D$2:$D$100),CountCalc!$D$2:$D$100,0))) | F2: =MAX(CountCalc!$D$2:$D$100) -> 0 | G2: =IF(MAX(Calc!$F$2:$F$31)=0,"",INDEX(Calc!$E$2:$E$31,MATCH(MAX(Calc!$F$2:$F$31),Calc!$F$2:$F$31,0))) | H2: =MAX(Calc!$F$2:$F$31) -> 0 | I2: =IF(H2=0,"",INDEX(Calc!$C$2:$C$31,MATCH(H2,Calc!$F$2:$F$31,0)))
A3: 2 | B3: ECHOPARK (ATLANTA) | C3: =IF(MAX(WeeklyPicks!$M$12:$M$21)=0,"",INDEX(WeeklyPicks!$C$12:$C$21,MATCH(MAX(WeeklyPicks!$M$12:$M$21),WeeklyPicks!$M$12:$M$21,0))) | D3: =MAX(WeeklyPicks!$M$12:$M$21) -> 0 | E3: =IF(MAX(CountCalc!$D$101:$D$199)=0,"",INDEX(CountCalc!$C$101:$C$199,MATCH(MAX(CountCalc!$D$101:$D$199),CountCalc!$D$101:$D$199,0))) | F3: =MAX(CountCalc!$D$101:$D$199) -> 0 | G3: =IF(MAX(Calc!$F$32:$F$61)=0,"",INDEX(Calc!$E$32:$E$61,MATCH(MAX(Calc!$F$32:$F$61),Calc!$F$32:$F$61,0))) | H3: =MAX(Calc!$F$32:$F$61) -> 0 | I3: =IF(H3=0,"",INDEX(Calc!$C$32:$C$61,MATCH(H3,Calc!$F$32:$F$61,0)))
A4: 3 | B4: COTA (AUSTIN) | C4: =IF(MAX(WeeklyPicks!$M$22:$M$31)=0,"",INDEX(WeeklyPicks!$C$22:$C$31,MATCH(MAX(WeeklyPicks!$M$22:$M$31),WeeklyPicks!$M$22:$M$31,0))) -> Meg | D4: =MAX(WeeklyPicks!$M$22:$M$31) -> 111 | E4: =IF(MAX(CountCalc!$D$200:$D$298)=0,"",INDEX(CountCalc!$C$200:$C$298,MATCH(MAX(CountCalc!$D$200:$D$298),CountCalc!$D$200:$D$298,0))) -> 11 | F4: =MAX(CountCalc!$D$200:$D$298) -> 2 | G4: =IF(MAX(Calc!$F$62:$F$91)=0,"",INDEX(Calc!$E$62:$E$91,MATCH(MAX(Calc!$F$62:$F$91),Calc!$F$62:$F$91,0))) -> 19 | H4: =MAX(Calc!$F$62:$F$91) -> 37 | I4: =IF(H4=0,"",INDEX(Calc!$C$62:$C$91,MATCH(H4,Calc!$F$62:$F$91,0))) -> Darin
A5: 4 | B5: PHOENIX | C5: =IF(MAX(WeeklyPicks!$M$32:$M$41)=0,"",INDEX(WeeklyPicks!$C$32:$C$41,MATCH(MAX(WeeklyPicks!$M$32:$M$41),WeeklyPicks!$M$32:$M$41,0))) -> Pat | D5: =MAX(WeeklyPicks!$M$32:$M$41) -> 95 | E5: =IF(MAX(CountCalc!$D$299:$D$397)=0,"",INDEX(CountCalc!$C$299:$C$397,MATCH(MAX(CountCalc!$D$299:$D$397),CountCalc!$D$299:$D$397,0))) -> 12 | F5: =MAX(CountCalc!$D$299:$D$397) -> 3 | G5: =IF(MAX(Calc!$F$92:$F$121)=0,"",INDEX(Calc!$E$92:$E$121,MATCH(MAX(Calc!$F$92:$F$121),Calc!$F$92:$F$121,0))) -> 19 | H5: =MAX(Calc!$F$92:$F$121) -> 37 | I5: =IF(H5=0,"",INDEX(Calc!$C$92:$C$121,MATCH(H5,Calc!$F$92:$F$121,0))) -> Joe
A6: 5 | B6: LAS VEGAS | C6: =IF(MAX(WeeklyPicks!$M$42:$M$51)=0,"",INDEX(WeeklyPicks!$C$42:$C$51,MATCH(MAX(WeeklyPicks!$M$42:$M$51),WeeklyPicks!$M$42:$M$51,0))) -> Joe | D6: =MAX(WeeklyPicks!$M$42:$M$51) -> 118 | E6: =IF(MAX(CountCalc!$D$398:$D$496)=0,"",INDEX(CountCalc!$C$398:$C$496,MATCH(MAX(CountCalc!$D$398:$D$496),CountCalc!$D$398:$D$496,0))) -> 5 | F6: =MAX(CountCalc!$D$398:$D$496) -> 4 | G6: =IF(MAX(Calc!$F$122:$F$151)=0,"",INDEX(Calc!$E$122:$E$151,MATCH(MAX(Calc!$F$122:$F$151),Calc!$F$122:$F$151,0))) -> 12 | H6: =MAX(Calc!$F$122:$F$151) -> 16 | I6: =IF(H6=0,"",INDEX(Calc!$C$122:$C$151,MATCH(H6,Calc!$F$122:$F$151,0))) -> Meg
A7: 6 | B7: DARLINGTON | C7: =IF(MAX(WeeklyPicks!$M$52:$M$61)=0,"",INDEX(WeeklyPicks!$C$52:$C$61,MATCH(MAX(WeeklyPicks!$M$52:$M$61),WeeklyPicks!$M$52:$M$61,0))) -> Alz | D7: =MAX(WeeklyPicks!$M$52:$M$61) -> 115 | E7: =IF(MAX(CountCalc!$D$497:$D$595)=0,"",INDEX(CountCalc!$C$497:$C$595,MATCH(MAX(CountCalc!$D$497:$D$595),CountCalc!$D$497:$D$595,0))) -> 11 | F7: =MAX(CountCalc!$D$497:$D$595) -> 7 | G7: =IF(MAX(Calc!$F$152:$F$181)=0,"",INDEX(Calc!$E$152:$E$181,MATCH(MAX(Calc!$F$152:$F$181),Calc!$F$152:$F$181,0))) -> 22 | H7: =MAX(Calc!$F$152:$F$181) -> 33 | I7: =IF(H7=0,"",INDEX(Calc!$C$152:$C$181,MATCH(H7,Calc!$F$152:$F$181,0))) -> Meg
A8: 7 | B8: MARTINSVILLE | C8: =IF(MAX(WeeklyPicks!$M$62:$M$71)=0,"",INDEX(WeeklyPicks!$C$62:$C$71,MATCH(MAX(WeeklyPicks!$M$62:$M$71),WeeklyPicks!$M$62:$M$71,0))) -> Darin | D8: =MAX(WeeklyPicks!$M$62:$M$71) -> 122 | E8: =IF(MAX(CountCalc!$D$596:$D$694)=0,"",INDEX(CountCalc!$C$596:$C$694,MATCH(MAX(CountCalc!$D$596:$D$694),CountCalc!$D$596:$D$694,0))) -> 11 | F8: =MAX(CountCalc!$D$596:$D$694) -> 8 | G8: =IF(MAX(Calc!$F$182:$F$211)=0,"",INDEX(Calc!$E$182:$E$211,MATCH(MAX(Calc!$F$182:$F$211),Calc!$F$182:$F$211,0))) -> 23 | H8: =MAX(Calc!$F$182:$F$211) -> 36 | I8: =IF(H8=0,"",INDEX(Calc!$C$182:$C$211,MATCH(H8,Calc!$F$182:$F$211,0))) -> Ryan
A9: 8 | B9: BRISTOL | C9: =IF(MAX(WeeklyPicks!$M$72:$M$81)=0,"",INDEX(WeeklyPicks!$C$72:$C$81,MATCH(MAX(WeeklyPicks!$M$72:$M$81),WeeklyPicks!$M$72:$M$81,0))) -> Ryan | D9: =MAX(WeeklyPicks!$M$72:$M$81) -> 123 | E9: =IF(MAX(CountCalc!$D$695:$D$793)=0,"",INDEX(CountCalc!$C$695:$C$793,MATCH(MAX(CountCalc!$D$695:$D$793),CountCalc!$D$695:$D$793,0))) -> 12 | F9: =MAX(CountCalc!$D$695:$D$793) -> 6 | G9: =IF(MAX(Calc!$F$212:$F$241)=0,"",INDEX(Calc!$E$212:$E$241,MATCH(MAX(Calc!$F$212:$F$241),Calc!$F$212:$F$241,0))) -> 20 | H9: =MAX(Calc!$F$212:$F$241) -> 27 | I9: =IF(H9=0,"",INDEX(Calc!$C$212:$C$241,MATCH(H9,Calc!$F$212:$F$241,0))) -> Joe
A10: 9 | B10: KANSAS | C10: =IF(MAX(WeeklyPicks!$M$82:$M$91)=0,"",INDEX(WeeklyPicks!$C$82:$C$91,MATCH(MAX(WeeklyPicks!$M$82:$M$91),WeeklyPicks!$M$82:$M$91,0))) -> Pat | D10: =MAX(WeeklyPicks!$M$82:$M$91) -> 123 | E10: =IF(MAX(CountCalc!$D$794:$D$892)=0,"",INDEX(CountCalc!$C$794:$C$892,MATCH(MAX(CountCalc!$D$794:$D$892),CountCalc!$D$794:$D$892,0))) -> 5 | F10: =MAX(CountCalc!$D$794:$D$892) -> 8 | G10: =IF(MAX(Calc!$F$242:$F$271)=0,"",INDEX(Calc!$E$242:$E$271,MATCH(MAX(Calc!$F$242:$F$271),Calc!$F$242:$F$271,0))) -> 12 | H10: =MAX(Calc!$F$242:$F$271) -> 24 | I10: =IF(H10=0,"",INDEX(Calc!$C$242:$C$271,MATCH(H10,Calc!$F$242:$F$271,0))) -> Darin
A11: 10 | B11: TALLADEGA | C11: =IF(MAX(WeeklyPicks!$M$92:$M$101)=0,"",INDEX(WeeklyPicks!$C$92:$C$101,MATCH(MAX(WeeklyPicks!$M$92:$M$101),WeeklyPicks!$M$92:$M$101,0))) -> Meg | D11: =MAX(WeeklyPicks!$M$92:$M$101) -> 46 | E11: =IF(MAX(CountCalc!$D$893:$D$991)=0,"",INDEX(CountCalc!$C$893:$C$991,MATCH(MAX(CountCalc!$D$893:$D$991),CountCalc!$D$893:$D$991,0))) -> 5 | F11: =MAX(CountCalc!$D$893:$D$991) -> 6 | G11: =IF(MAX(Calc!$F$272:$F$301)=0,"",INDEX(Calc!$E$272:$E$301,MATCH(MAX(Calc!$F$272:$F$301),Calc!$F$272:$F$301,0))) -> 5 | H11: =MAX(Calc!$F$272:$F$301) -> 40 | I11: =IF(H11=0,"",INDEX(Calc!$C$272:$C$301,MATCH(H11,Calc!$F$272:$F$301,0))) -> Pat
A12: 11 | B12: TEXAS | C12: =IF(MAX(WeeklyPicks!$M$102:$M$111)=0,"",INDEX(WeeklyPicks!$C$102:$C$111,MATCH(MAX(WeeklyPicks!$M$102:$M$111),WeeklyPicks!$M$102:$M$111,0))) -> Meg | D12: =MAX(WeeklyPicks!$M$102:$M$111) -> 99 | E12: =IF(MAX(CountCalc!$D$992:$D$1090)=0,"",INDEX(CountCalc!$C$992:$C$1090,MATCH(MAX(CountCalc!$D$992:$D$1090),CountCalc!$D$992:$D$1090,0))) -> 11 | F12: =MAX(CountCalc!$D$992:$D$1090) -> 6 | G12: =IF(MAX(Calc!$F$302:$F$331)=0,"",INDEX(Calc!$E$302:$E$331,MATCH(MAX(Calc!$F$302:$F$331),Calc!$F$302:$F$331,0))) -> 20 | H12: =MAX(Calc!$F$302:$F$331) -> 38 | I12: =IF(H12=0,"",INDEX(Calc!$C$302:$C$331,MATCH(H12,Calc!$F$302:$F$331,0))) -> Darin
A13: 12 | B13: WATKINS GLEN | C13: =IF(MAX(WeeklyPicks!$M$112:$M$121)=0,"",INDEX(WeeklyPicks!$C$112:$C$121,MATCH(MAX(WeeklyPicks!$M$112:$M$121),WeeklyPicks!$M$112:$M$121,0))) -> Pat | D13: =MAX(WeeklyPicks!$M$112:$M$121) -> 109 | E13: =IF(MAX(CountCalc!$D$1091:$D$1189)=0,"",INDEX(CountCalc!$C$1091:$C$1189,MATCH(MAX(CountCalc!$D$1091:$D$1189),CountCalc!$D$1091:$D$1189,0))) -> 97 | F13: =MAX(CountCalc!$D$1091:$D$1189) -> 6 | G13: =IF(MAX(Calc!$F$332:$F$361)=0,"",INDEX(Calc!$E$332:$E$361,MATCH(MAX(Calc!$F$332:$F$361),Calc!$F$332:$F$361,0))) -> 22 | H13: =MAX(Calc!$F$332:$F$361) -> 38 | I13: =IF(H13=0,"",INDEX(Calc!$C$332:$C$361,MATCH(H13,Calc!$F$332:$F$361,0))) -> Joe
A14: 13 | B14: CHARLOTTE | C14: =IF(MAX(WeeklyPicks!$M$122:$M$131)=0,"",INDEX(WeeklyPicks!$C$122:$C$131,MATCH(MAX(WeeklyPicks!$M$122:$M$131),WeeklyPicks!$M$122:$M$131,0))) | D14: =MAX(WeeklyPicks!$M$122:$M$131) -> 0 | E14: =IF(MAX(CountCalc!$D$1190:$D$1288)=0,"",INDEX(CountCalc!$C$1190:$C$1288,MATCH(MAX(CountCalc!$D$1190:$D$1288),CountCalc!$D$1190:$D$1288,0))) -> 11 | F14: =MAX(CountCalc!$D$1190:$D$1288) -> 5 | G14: =IF(MAX(Calc!$F$362:$F$391)=0,"",INDEX(Calc!$E$362:$E$391,MATCH(MAX(Calc!$F$362:$F$391),Calc!$F$362:$F$391,0))) | H14: =MAX(Calc!$F$362:$F$391) -> 0 | I14: =IF(H14=0,"",INDEX(Calc!$C$362:$C$391,MATCH(H14,Calc!$F$362:$F$391,0)))
A15: 14 | B15: NASHVILLE | C15: =IF(MAX(WeeklyPicks!$M$132:$M$141)=0,"",INDEX(WeeklyPicks!$C$132:$C$141,MATCH(MAX(WeeklyPicks!$M$132:$M$141),WeeklyPicks!$M$132:$M$141,0))) | D15: =MAX(WeeklyPicks!$M$132:$M$141) -> 0 | E15: =IF(MAX(CountCalc!$D$1289:$D$1387)=0,"",INDEX(CountCalc!$C$1289:$C$1387,MATCH(MAX(CountCalc!$D$1289:$D$1387),CountCalc!$D$1289:$D$1387,0))) | F15: =MAX(CountCalc!$D$1289:$D$1387) -> 0 | G15: =IF(MAX(Calc!$F$392:$F$421)=0,"",INDEX(Calc!$E$392:$E$421,MATCH(MAX(Calc!$F$392:$F$421),Calc!$F$392:$F$421,0))) | H15: =MAX(Calc!$F$392:$F$421) -> 0 | I15: =IF(H15=0,"",INDEX(Calc!$C$392:$C$421,MATCH(H15,Calc!$F$392:$F$421,0)))
A16: 15 | B16: MICHIGAN | C16: =IF(MAX(WeeklyPicks!$M$142:$M$151)=0,"",INDEX(WeeklyPicks!$C$142:$C$151,MATCH(MAX(WeeklyPicks!$M$142:$M$151),WeeklyPicks!$M$142:$M$151,0))) | D16: =MAX(WeeklyPicks!$M$142:$M$151) -> 0 | E16: =IF(MAX(CountCalc!$D$1388:$D$1486)=0,"",INDEX(CountCalc!$C$1388:$C$1486,MATCH(MAX(CountCalc!$D$1388:$D$1486),CountCalc!$D$1388:$D$1486,0))) | F16: =MAX(CountCalc!$D$1388:$D$1486) -> 0 | G16: =IF(MAX(Calc!$F$422:$F$451)=0,"",INDEX(Calc!$E$422:$E$451,MATCH(MAX(Calc!$F$422:$F$451),Calc!$F$422:$F$451,0))) | H16: =MAX(Calc!$F$422:$F$451) -> 0 | I16: =IF(H16=0,"",INDEX(Calc!$C$422:$C$451,MATCH(H16,Calc!$F$422:$F$451,0)))
A17: 16 | B17: POCONO | C17: =IF(MAX(WeeklyPicks!$M$152:$M$161)=0,"",INDEX(WeeklyPicks!$C$152:$C$161,MATCH(MAX(WeeklyPicks!$M$152:$M$161),WeeklyPicks!$M$152:$M$161,0))) | D17: =MAX(WeeklyPicks!$M$152:$M$161) -> 0 | E17: =IF(MAX(CountCalc!$D$1487:$D$1585)=0,"",INDEX(CountCalc!$C$1487:$C$1585,MATCH(MAX(CountCalc!$D$1487:$D$1585),CountCalc!$D$1487:$D$1585,0))) | F17: =MAX(CountCalc!$D$1487:$D$1585) -> 0 | G17: =IF(MAX(Calc!$F$452:$F$481)=0,"",INDEX(Calc!$E$452:$E$481,MATCH(MAX(Calc!$F$452:$F$481),Calc!$F$452:$F$481,0))) | H17: =MAX(Calc!$F$452:$F$481) -> 0 | I17: =IF(H17=0,"",INDEX(Calc!$C$452:$C$481,MATCH(H17,Calc!$F$452:$F$481,0)))
A18: 17 | B18: SAN DIEGO | C18: =IF(MAX(WeeklyPicks!$M$162:$M$171)=0,"",INDEX(WeeklyPicks!$C$162:$C$171,MATCH(MAX(WeeklyPicks!$M$162:$M$171),WeeklyPicks!$M$162:$M$171,0))) | D18: =MAX(WeeklyPicks!$M$162:$M$171) -> 0 | E18: =IF(MAX(CountCalc!$D$1586:$D$1684)=0,"",INDEX(CountCalc!$C$1586:$C$1684,MATCH(MAX(CountCalc!$D$1586:$D$1684),CountCalc!$D$1586:$D$1684,0))) | F18: =MAX(CountCalc!$D$1586:$D$1684) -> 0 | G18: =IF(MAX(Calc!$F$482:$F$511)=0,"",INDEX(Calc!$E$482:$E$511,MATCH(MAX(Calc!$F$482:$F$511),Calc!$F$482:$F$511,0))) | H18: =MAX(Calc!$F$482:$F$511) -> 0 | I18: =IF(H18=0,"",INDEX(Calc!$C$482:$C$511,MATCH(H18,Calc!$F$482:$F$511,0)))
A19: 18 | B19: SONOMA | C19: =IF(MAX(WeeklyPicks!$M$172:$M$181)=0,"",INDEX(WeeklyPicks!$C$172:$C$181,MATCH(MAX(WeeklyPicks!$M$172:$M$181),WeeklyPicks!$M$172:$M$181,0))) | D19: =MAX(WeeklyPicks!$M$172:$M$181) -> 0 | E19: =IF(MAX(CountCalc!$D$1685:$D$1783)=0,"",INDEX(CountCalc!$C$1685:$C$1783,MATCH(MAX(CountCalc!$D$1685:$D$1783),CountCalc!$D$1685:$D$1783,0))) | F19: =MAX(CountCalc!$D$1685:$D$1783) -> 0 | G19: =IF(MAX(Calc!$F$512:$F$541)=0,"",INDEX(Calc!$E$512:$E$541,MATCH(MAX(Calc!$F$512:$F$541),Calc!$F$512:$F$541,0))) | H19: =MAX(Calc!$F$512:$F$541) -> 0 | I19: =IF(H19=0,"",INDEX(Calc!$C$512:$C$541,MATCH(H19,Calc!$F$512:$F$541,0)))
A20: 19 | B20: CHICAGOLAND | C20: =IF(MAX(WeeklyPicks!$M$182:$M$191)=0,"",INDEX(WeeklyPicks!$C$182:$C$191,MATCH(MAX(WeeklyPicks!$M$182:$M$191),WeeklyPicks!$M$182:$M$191,0))) | D20: =MAX(WeeklyPicks!$M$182:$M$191) -> 0 | E20: =IF(MAX(CountCalc!$D$1784:$D$1882)=0,"",INDEX(CountCalc!$C$1784:$C$1882,MATCH(MAX(CountCalc!$D$1784:$D$1882),CountCalc!$D$1784:$D$1882,0))) | F20: =MAX(CountCalc!$D$1784:$D$1882) -> 0 | G20: =IF(MAX(Calc!$F$542:$F$571)=0,"",INDEX(Calc!$E$542:$E$571,MATCH(MAX(Calc!$F$542:$F$571),Calc!$F$542:$F$571,0))) | H20: =MAX(Calc!$F$542:$F$571) -> 0 | I20: =IF(H20=0,"",INDEX(Calc!$C$542:$C$571,MATCH(H20,Calc!$F$542:$F$571,0)))
A21: 20 | B21: ECHOPARK (ATLANTA) | C21: =IF(MAX(WeeklyPicks!$M$192:$M$201)=0,"",INDEX(WeeklyPicks!$C$192:$C$201,MATCH(MAX(WeeklyPicks!$M$192:$M$201),WeeklyPicks!$M$192:$M$201,0))) | D21: =MAX(WeeklyPicks!$M$192:$M$201) -> 0 | E21: =IF(MAX(CountCalc!$D$1883:$D$1981)=0,"",INDEX(CountCalc!$C$1883:$C$1981,MATCH(MAX(CountCalc!$D$1883:$D$1981),CountCalc!$D$1883:$D$1981,0))) | F21: =MAX(CountCalc!$D$1883:$D$1981) -> 0 | G21: =IF(MAX(Calc!$F$572:$F$601)=0,"",INDEX(Calc!$E$572:$E$601,MATCH(MAX(Calc!$F$572:$F$601),Calc!$F$572:$F$601,0))) | H21: =MAX(Calc!$F$572:$F$601) -> 0 | I21: =IF(H21=0,"",INDEX(Calc!$C$572:$C$601,MATCH(H21,Calc!$F$572:$F$601,0)))
A22: 21 | B22: NORTH WILKESBORO | C22: =IF(MAX(WeeklyPicks!$M$202:$M$211)=0,"",INDEX(WeeklyPicks!$C$202:$C$211,MATCH(MAX(WeeklyPicks!$M$202:$M$211),WeeklyPicks!$M$202:$M$211,0))) | D22: =MAX(WeeklyPicks!$M$202:$M$211) -> 0 | E22: =IF(MAX(CountCalc!$D$1982:$D$2080)=0,"",INDEX(CountCalc!$C$1982:$C$2080,MATCH(MAX(CountCalc!$D$1982:$D$2080),CountCalc!$D$1982:$D$2080,0))) | F22: =MAX(CountCalc!$D$1982:$D$2080) -> 0 | G22: =IF(MAX(Calc!$F$602:$F$631)=0,"",INDEX(Calc!$E$602:$E$631,MATCH(MAX(Calc!$F$602:$F$631),Calc!$F$602:$F$631,0))) | H22: =MAX(Calc!$F$602:$F$631) -> 0 | I22: =IF(H22=0,"",INDEX(Calc!$C$602:$C$631,MATCH(H22,Calc!$F$602:$F$631,0)))
A23: 22 | B23: INDIANAPOLIS | C23: =IF(MAX(WeeklyPicks!$M$212:$M$221)=0,"",INDEX(WeeklyPicks!$C$212:$C$221,MATCH(MAX(WeeklyPicks!$M$212:$M$221),WeeklyPicks!$M$212:$M$221,0))) | D23: =MAX(WeeklyPicks!$M$212:$M$221) -> 0 | E23: =IF(MAX(CountCalc!$D$2081:$D$2179)=0,"",INDEX(CountCalc!$C$2081:$C$2179,MATCH(MAX(CountCalc!$D$2081:$D$2179),CountCalc!$D$2081:$D$2179,0))) | F23: =MAX(CountCalc!$D$2081:$D$2179) -> 0 | G23: =IF(MAX(Calc!$F$632:$F$661)=0,"",INDEX(Calc!$E$632:$E$661,MATCH(MAX(Calc!$F$632:$F$661),Calc!$F$632:$F$661,0))) | H23: =MAX(Calc!$F$632:$F$661) -> 0 | I23: =IF(H23=0,"",INDEX(Calc!$C$632:$C$661,MATCH(H23,Calc!$F$632:$F$661,0)))
A24: 23 | B24: IOWA | C24: =IF(MAX(WeeklyPicks!$M$222:$M$231)=0,"",INDEX(WeeklyPicks!$C$222:$C$231,MATCH(MAX(WeeklyPicks!$M$222:$M$231),WeeklyPicks!$M$222:$M$231,0))) | D24: =MAX(WeeklyPicks!$M$222:$M$231) -> 0 | E24: =IF(MAX(CountCalc!$D$2180:$D$2278)=0,"",INDEX(CountCalc!$C$2180:$C$2278,MATCH(MAX(CountCalc!$D$2180:$D$2278),CountCalc!$D$2180:$D$2278,0))) | F24: =MAX(CountCalc!$D$2180:$D$2278) -> 0 | G24: =IF(MAX(Calc!$F$662:$F$691)=0,"",INDEX(Calc!$E$662:$E$691,MATCH(MAX(Calc!$F$662:$F$691),Calc!$F$662:$F$691,0))) | H24: =MAX(Calc!$F$662:$F$691) -> 0 | I24: =IF(H24=0,"",INDEX(Calc!$C$662:$C$691,MATCH(H24,Calc!$F$662:$F$691,0)))
A25: 24 | B25: RICHMOND | C25: =IF(MAX(WeeklyPicks!$M$232:$M$241)=0,"",INDEX(WeeklyPicks!$C$232:$C$241,MATCH(MAX(WeeklyPicks!$M$232:$M$241),WeeklyPicks!$M$232:$M$241,0))) | D25: =MAX(WeeklyPicks!$M$232:$M$241) -> 0 | E25: =IF(MAX(CountCalc!$D$2279:$D$2377)=0,"",INDEX(CountCalc!$C$2279:$C$2377,MATCH(MAX(CountCalc!$D$2279:$D$2377),CountCalc!$D$2279:$D$2377,0))) | F25: =MAX(CountCalc!$D$2279:$D$2377) -> 0 | G25: =IF(MAX(Calc!$F$692:$F$721)=0,"",INDEX(Calc!$E$692:$E$721,MATCH(MAX(Calc!$F$692:$F$721),Calc!$F$692:$F$721,0))) | H25: =MAX(Calc!$F$692:$F$721) -> 0 | I25: =IF(H25=0,"",INDEX(Calc!$C$692:$C$721,MATCH(H25,Calc!$F$692:$F$721,0)))
A26: 25 | B26: NEW HAMPSHIRE | C26: =IF(MAX(WeeklyPicks!$M$242:$M$251)=0,"",INDEX(WeeklyPicks!$C$242:$C$251,MATCH(MAX(WeeklyPicks!$M$242:$M$251),WeeklyPicks!$M$242:$M$251,0))) | D26: =MAX(WeeklyPicks!$M$242:$M$251) -> 0 | E26: =IF(MAX(CountCalc!$D$2378:$D$2476)=0,"",INDEX(CountCalc!$C$2378:$C$2476,MATCH(MAX(CountCalc!$D$2378:$D$2476),CountCalc!$D$2378:$D$2476,0))) | F26: =MAX(CountCalc!$D$2378:$D$2476) -> 0 | G26: =IF(MAX(Calc!$F$722:$F$751)=0,"",INDEX(Calc!$E$722:$E$751,MATCH(MAX(Calc!$F$722:$F$751),Calc!$F$722:$F$751,0))) | H26: =MAX(Calc!$F$722:$F$751) -> 0 | I26: =IF(H26=0,"",INDEX(Calc!$C$722:$C$751,MATCH(H26,Calc!$F$722:$F$751,0)))
A27: 26 | B27: DAYTONA | C27: =IF(MAX(WeeklyPicks!$M$252:$M$261)=0,"",INDEX(WeeklyPicks!$C$252:$C$261,MATCH(MAX(WeeklyPicks!$M$252:$M$261),WeeklyPicks!$M$252:$M$261,0))) | D27: =MAX(WeeklyPicks!$M$252:$M$261) -> 0 | E27: =IF(MAX(CountCalc!$D$2477:$D$2575)=0,"",INDEX(CountCalc!$C$2477:$C$2575,MATCH(MAX(CountCalc!$D$2477:$D$2575),CountCalc!$D$2477:$D$2575,0))) | F27: =MAX(CountCalc!$D$2477:$D$2575) -> 0 | G27: =IF(MAX(Calc!$F$752:$F$781)=0,"",INDEX(Calc!$E$752:$E$781,MATCH(MAX(Calc!$F$752:$F$781),Calc!$F$752:$F$781,0))) | H27: =MAX(Calc!$F$752:$F$781) -> 0 | I27: =IF(H27=0,"",INDEX(Calc!$C$752:$C$781,MATCH(H27,Calc!$F$752:$F$781,0)))
A28: 27 | B28: DARLINGTON | C28: =IF(MAX(WeeklyPicks!$M$262:$M$271)=0,"",INDEX(WeeklyPicks!$C$262:$C$271,MATCH(MAX(WeeklyPicks!$M$262:$M$271),WeeklyPicks!$M$262:$M$271,0))) | D28: =MAX(WeeklyPicks!$M$262:$M$271) -> 0 | E28: =IF(MAX(CountCalc!$D$2576:$D$2674)=0,"",INDEX(CountCalc!$C$2576:$C$2674,MATCH(MAX(CountCalc!$D$2576:$D$2674),CountCalc!$D$2576:$D$2674,0))) | F28: =MAX(CountCalc!$D$2576:$D$2674) -> 0 | G28: =IF(MAX(Calc!$F$782:$F$811)=0,"",INDEX(Calc!$E$782:$E$811,MATCH(MAX(Calc!$F$782:$F$811),Calc!$F$782:$F$811,0))) | H28: =MAX(Calc!$F$782:$F$811) -> 0 | I28: =IF(H28=0,"",INDEX(Calc!$C$782:$C$811,MATCH(H28,Calc!$F$782:$F$811,0)))
A29: 28 | B29: WWTR (ST. LOUIS) | C29: =IF(MAX(WeeklyPicks!$M$272:$M$281)=0,"",INDEX(WeeklyPicks!$C$272:$C$281,MATCH(MAX(WeeklyPicks!$M$272:$M$281),WeeklyPicks!$M$272:$M$281,0))) | D29: =MAX(WeeklyPicks!$M$272:$M$281) -> 0 | E29: =IF(MAX(CountCalc!$D$2675:$D$2773)=0,"",INDEX(CountCalc!$C$2675:$C$2773,MATCH(MAX(CountCalc!$D$2675:$D$2773),CountCalc!$D$2675:$D$2773,0))) | F29: =MAX(CountCalc!$D$2675:$D$2773) -> 0 | G29: =IF(MAX(Calc!$F$812:$F$841)=0,"",INDEX(Calc!$E$812:$E$841,MATCH(MAX(Calc!$F$812:$F$841),Calc!$F$812:$F$841,0))) | H29: =MAX(Calc!$F$812:$F$841) -> 0 | I29: =IF(H29=0,"",INDEX(Calc!$C$812:$C$841,MATCH(H29,Calc!$F$812:$F$841,0)))
A30: 29 | B30: BRISTOL | C30: =IF(MAX(WeeklyPicks!$M$282:$M$291)=0,"",INDEX(WeeklyPicks!$C$282:$C$291,MATCH(MAX(WeeklyPicks!$M$282:$M$291),WeeklyPicks!$M$282:$M$291,0))) | D30: =MAX(WeeklyPicks!$M$282:$M$291) -> 0 | E30: =IF(MAX(CountCalc!$D$2774:$D$2872)=0,"",INDEX(CountCalc!$C$2774:$C$2872,MATCH(MAX(CountCalc!$D$2774:$D$2872),CountCalc!$D$2774:$D$2872,0))) | F30: =MAX(CountCalc!$D$2774:$D$2872) -> 0 | G30: =IF(MAX(Calc!$F$842:$F$871)=0,"",INDEX(Calc!$E$842:$E$871,MATCH(MAX(Calc!$F$842:$F$871),Calc!$F$842:$F$871,0))) | H30: =MAX(Calc!$F$842:$F$871) -> 0 | I30: =IF(H30=0,"",INDEX(Calc!$C$842:$C$871,MATCH(H30,Calc!$F$842:$F$871,0)))
A31: 30 | B31: KANSAS | C31: =IF(MAX(WeeklyPicks!$M$292:$M$301)=0,"",INDEX(WeeklyPicks!$C$292:$C$301,MATCH(MAX(WeeklyPicks!$M$292:$M$301),WeeklyPicks!$M$292:$M$301,0))) | D31: =MAX(WeeklyPicks!$M$292:$M$301) -> 0 | E31: =IF(MAX(CountCalc!$D$2873:$D$2971)=0,"",INDEX(CountCalc!$C$2873:$C$2971,MATCH(MAX(CountCalc!$D$2873:$D$2971),CountCalc!$D$2873:$D$2971,0))) | F31: =MAX(CountCalc!$D$2873:$D$2971) -> 0 | G31: =IF(MAX(Calc!$F$872:$F$901)=0,"",INDEX(Calc!$E$872:$E$901,MATCH(MAX(Calc!$F$872:$F$901),Calc!$F$872:$F$901,0))) | H31: =MAX(Calc!$F$872:$F$901) -> 0 | I31: =IF(H31=0,"",INDEX(Calc!$C$872:$C$901,MATCH(H31,Calc!$F$872:$F$901,0)))
A32: 31 | B32: LAS VEGAS | C32: =IF(MAX(WeeklyPicks!$M$302:$M$311)=0,"",INDEX(WeeklyPicks!$C$302:$C$311,MATCH(MAX(WeeklyPicks!$M$302:$M$311),WeeklyPicks!$M$302:$M$311,0))) | D32: =MAX(WeeklyPicks!$M$302:$M$311) -> 0 | E32: =IF(MAX(CountCalc!$D$2972:$D$3070)=0,"",INDEX(CountCalc!$C$2972:$C$3070,MATCH(MAX(CountCalc!$D$2972:$D$3070),CountCalc!$D$2972:$D$3070,0))) | F32: =MAX(CountCalc!$D$2972:$D$3070) -> 0 | G32: =IF(MAX(Calc!$F$902:$F$931)=0,"",INDEX(Calc!$E$902:$E$931,MATCH(MAX(Calc!$F$902:$F$931),Calc!$F$902:$F$931,0))) | H32: =MAX(Calc!$F$902:$F$931) -> 0 | I32: =IF(H32=0,"",INDEX(Calc!$C$902:$C$931,MATCH(H32,Calc!$F$902:$F$931,0)))
A33: 32 | B33: CHARLOTTE | C33: =IF(MAX(WeeklyPicks!$M$312:$M$321)=0,"",INDEX(WeeklyPicks!$C$312:$C$321,MATCH(MAX(WeeklyPicks!$M$312:$M$321),WeeklyPicks!$M$312:$M$321,0))) | D33: =MAX(WeeklyPicks!$M$312:$M$321) -> 0 | E33: =IF(MAX(CountCalc!$D$3071:$D$3169)=0,"",INDEX(CountCalc!$C$3071:$C$3169,MATCH(MAX(CountCalc!$D$3071:$D$3169),CountCalc!$D$3071:$D$3169,0))) | F33: =MAX(CountCalc!$D$3071:$D$3169) -> 0 | G33: =IF(MAX(Calc!$F$932:$F$961)=0,"",INDEX(Calc!$E$932:$E$961,MATCH(MAX(Calc!$F$932:$F$961),Calc!$F$932:$F$961,0))) | H33: =MAX(Calc!$F$932:$F$961) -> 0 | I33: =IF(H33=0,"",INDEX(Calc!$C$932:$C$961,MATCH(H33,Calc!$F$932:$F$961,0)))
A34: 33 | B34: PHOENIX | C34: =IF(MAX(WeeklyPicks!$M$322:$M$331)=0,"",INDEX(WeeklyPicks!$C$322:$C$331,MATCH(MAX(WeeklyPicks!$M$322:$M$331),WeeklyPicks!$M$322:$M$331,0))) | D34: =MAX(WeeklyPicks!$M$322:$M$331) -> 0 | E34: =IF(MAX(CountCalc!$D$3170:$D$3268)=0,"",INDEX(CountCalc!$C$3170:$C$3268,MATCH(MAX(CountCalc!$D$3170:$D$3268),CountCalc!$D$3170:$D$3268,0))) | F34: =MAX(CountCalc!$D$3170:$D$3268) -> 0 | G34: =IF(MAX(Calc!$F$962:$F$991)=0,"",INDEX(Calc!$E$962:$E$991,MATCH(MAX(Calc!$F$962:$F$991),Calc!$F$962:$F$991,0))) | H34: =MAX(Calc!$F$962:$F$991) -> 0 | I34: =IF(H34=0,"",INDEX(Calc!$C$962:$C$991,MATCH(H34,Calc!$F$962:$F$991,0)))
A35: 34 | B35: TALLADEGA | C35: =IF(MAX(WeeklyPicks!$M$332:$M$341)=0,"",INDEX(WeeklyPicks!$C$332:$C$341,MATCH(MAX(WeeklyPicks!$M$332:$M$341),WeeklyPicks!$M$332:$M$341,0))) | D35: =MAX(WeeklyPicks!$M$332:$M$341) -> 0 | E35: =IF(MAX(CountCalc!$D$3269:$D$3367)=0,"",INDEX(CountCalc!$C$3269:$C$3367,MATCH(MAX(CountCalc!$D$3269:$D$3367),CountCalc!$D$3269:$D$3367,0))) | F35: =MAX(CountCalc!$D$3269:$D$3367) -> 0 | G35: =IF(MAX(Calc!$F$992:$F$1021)=0,"",INDEX(Calc!$E$992:$E$1021,MATCH(MAX(Calc!$F$992:$F$1021),Calc!$F$992:$F$1021,0))) | H35: =MAX(Calc!$F$992:$F$1021) -> 0 | I35: =IF(H35=0,"",INDEX(Calc!$C$992:$C$1021,MATCH(H35,Calc!$F$992:$F$1021,0)))
A36: 35 | B36: MARTINSVILLE | C36: =IF(MAX(WeeklyPicks!$M$342:$M$351)=0,"",INDEX(WeeklyPicks!$C$342:$C$351,MATCH(MAX(WeeklyPicks!$M$342:$M$351),WeeklyPicks!$M$342:$M$351,0))) | D36: =MAX(WeeklyPicks!$M$342:$M$351) -> 0 | E36: =IF(MAX(CountCalc!$D$3368:$D$3466)=0,"",INDEX(CountCalc!$C$3368:$C$3466,MATCH(MAX(CountCalc!$D$3368:$D$3466),CountCalc!$D$3368:$D$3466,0))) | F36: =MAX(CountCalc!$D$3368:$D$3466) -> 0 | G36: =IF(MAX(Calc!$F$1022:$F$1051)=0,"",INDEX(Calc!$E$1022:$E$1051,MATCH(MAX(Calc!$F$1022:$F$1051),Calc!$F$1022:$F$1051,0))) | H36: =MAX(Calc!$F$1022:$F$1051) -> 0 | I36: =IF(H36=0,"",INDEX(Calc!$C$1022:$C$1051,MATCH(H36,Calc!$F$1022:$F$1051,0)))
A37: 36 | B37: HOMESTEAD-MIAMI | C37: =IF(MAX(WeeklyPicks!$M$352:$M$361)=0,"",INDEX(WeeklyPicks!$C$352:$C$361,MATCH(MAX(WeeklyPicks!$M$352:$M$361),WeeklyPicks!$M$352:$M$361,0))) | D37: =MAX(WeeklyPicks!$M$352:$M$361) -> 0 | E37: =IF(MAX(CountCalc!$D$3467:$D$3565)=0,"",INDEX(CountCalc!$C$3467:$C$3565,MATCH(MAX(CountCalc!$D$3467:$D$3565),CountCalc!$D$3467:$D$3565,0))) | F37: =MAX(CountCalc!$D$3467:$D$3565) -> 0 | G37: =IF(MAX(Calc!$F$1052:$F$1081)=0,"",INDEX(Calc!$E$1052:$E$1081,MATCH(MAX(Calc!$F$1052:$F$1081),Calc!$F$1052:$F$1081,0))) | H37: =MAX(Calc!$F$1052:$F$1081) -> 0 | I37: =IF(H37=0,"",INDEX(Calc!$C$1052:$C$1081,MATCH(H37,Calc!$F$1052:$F$1081,0)))

Sheet RaceResults
A1: Race # | B1: Race | C1: Finish | D1: Car # | E1: Finish Pts
A2: 1 | B2: DAYTONA 500 | C2: 1 | D2: 45 | E2: =IF(C2="","",VLOOKUP(C2,PointsSystem!$A$2:$B$41,2,FALSE())) -> 55
A3: 1 | B3: DAYTONA 500 | C3: 2 | D3: 47 | E3: =IF(C3="","",VLOOKUP(C3,PointsSystem!$A$2:$B$41,2,FALSE())) -> 35
A4: 1 | B4: DAYTONA 500 | C4: 3 | D4: 22 | E4: =IF(C4="","",VLOOKUP(C4,PointsSystem!$A$2:$B$41,2,FALSE())) -> 34
A5: 1 | B5: DAYTONA 500 | C5: 4 | D5: 9 | E5: =IF(C5="","",VLOOKUP(C5,PointsSystem!$A$2:$B$41,2,FALSE())) -> 33
A6: 1 | B6: DAYTONA 500 | C6: 5 | D6: 6 | E6: =IF(C6="","",VLOOKUP(C6,PointsSystem!$A$2:$B$41,2,FALSE())) -> 32
A7: 1 | B7: DAYTONA 500 | C7: 6 | D7: 38 | E7: =IF(C7="","",VLOOKUP(C7,PointsSystem!$A$2:$B$41,2,FALSE())) -> 31
A8: 1 | B8: DAYTONA 500 | C8: 7 | D8: 17 | E8: =IF(C8="","",VLOOKUP(C8,PointsSystem!$A$2:$B$41,2,FALSE())) -> 30
A9: 1 | B9: DAYTONA 500 | C9: 8 | D9: 35 | E9: =IF(C9="","",VLOOKUP(C9,PointsSystem!$A$2:$B$41,2,FALSE())) -> 29
A10: 1 | B10: DAYTONA 500 | C10: 9 | D10: 21 | E10: =IF(C10="","",VLOOKUP(C10,PointsSystem!$A$2:$B$41,2,FALSE())) -> 28
A11: 1 | B11: DAYTONA 500 | C11: 10 | D11: 23 | E11: =IF(C11="","",VLOOKUP(C11,PointsSystem!$A$2:$B$41,2,FALSE())) -> 27
A12: 1 | B12: DAYTONA 500 | C12: 11 | D12: 4 | E12: =IF(C12="","",VLOOKUP(C12,PointsSystem!$A$2:$B$41,2,FALSE())) -> 26
A13: 1 | B13: DAYTONA 500 | C13: 12 | D13: 24 | E13: =IF(C13="","",VLOOKUP(C13,PointsSystem!$A$2:$B$41,2,FALSE())) -> 25
... A41: 1 | B41: DAYTONA 500 | C41: 40 | D41: 48 | E41: =IF(C41="","",VLOOKUP(C41,PointsSystem!$A$2:$B$41,2,FALSE())) -> 1
A42: 1 | B42: DAYTONA 500 | C42: 41 | D42: 78 | E42: 1
A43: 2 | B43: ECHOPARK (ATLANTA) | C43: 1 | D43: 45 | E43: =IF(C43="","",VLOOKUP(C43,PointsSystem!$A$2:$B$41,2,FALSE())) -> 55
A44: 2 | B44: ECHOPARK (ATLANTA) | C44: 2 | D44: 19 | E44: =IF(C44="","",VLOOKUP(C44,PointsSystem!$A$2:$B$41,2,FALSE())) -> 35
A45: 2 | B45: ECHOPARK (ATLANTA) | C45: 3 | D45: 1 | E45: =IF(C45="","",VLOOKUP(C45,PointsSystem!$A$2:$B$41,2,FALSE())) -> 34
A46: 2 | B46: ECHOPARK (ATLANTA) | C46: 4 | D46: 77 | E46: =IF(C46="","",VLOOKUP(C46,PointsSystem!$A$2:$B$41,2,FALSE())) -> 33
A47: 2 | B47: ECHOPARK (ATLANTA) | C47: 5 | D47: 7 | E47: =IF(C47="","",VLOOKUP(C47,PointsSystem!$A$2:$B$41,2,FALSE())) -> 32
A48: 2 | B48: ECHOPARK (ATLANTA) | C48: 6 | D48: 97 | E48: =IF(C48="","",VLOOKUP(C48,PointsSystem!$A$2:$B$41,2,FALSE())) -> 31
A49: 2 | B49: ECHOPARK (ATLANTA) | C49: 7 | D49: 38 | E49: =IF(C49="","",VLOOKUP(C49,PointsSystem!$A$2:$B$41,2,FALSE())) -> 30
A50: 2 | B50: ECHOPARK (ATLANTA) | C50: 8 | D50: 23 | E50: =IF(C50="","",VLOOKUP(C50,PointsSystem!$A$2:$B$41,2,FALSE())) -> 29
A51: 2 | B51: ECHOPARK (ATLANTA) | C51: 9 | D51: 60 | E51: =IF(C51="","",VLOOKUP(C51,PointsSystem!$A$2:$B$41,2,FALSE())) -> 28
A52: 2 | B52: ECHOPARK (ATLANTA) | C52: 10 | D52: 12 | E52: =IF(C52="","",VLOOKUP(C52,PointsSystem!$A$2:$B$41,2,FALSE())) -> 27
A53: 2 | B53: ECHOPARK (ATLANTA) | C53: 11 | D53: 9 | E53: =IF(C53="","",VLOOKUP(C53,PointsSystem!$A$2:$B$41,2,FALSE())) -> 26
A54: 2 | B54: ECHOPARK (ATLANTA) | C54: 12 | D54: 16 | E54: =IF(C54="","",VLOOKUP(C54,PointsSystem!$A$2:$B$41,2,FALSE())) -> 25
... A78: 2 | B78: ECHOPARK (ATLANTA) | C78: 36 | D78: 47 | E78: =IF(C78="","",VLOOKUP(C78,PointsSystem!$A$2:$B$41,2,FALSE())) -> 1
A79: 2 | B79: ECHOPARK (ATLANTA) | C79: 37 | D79: 54 | E79: 1
A80: 2 | B80: ECHOPARK (ATLANTA) | C80: 38 | D80: 21 | E80: =IF(C80="","",VLOOKUP(C80,PointsSystem!$A$2:$B$41,2,FALSE())) -> 1
A81: 2 | B81: ECHOPARK (ATLANTA) | C81: 39 | E81: =IF(C81="","",VLOOKUP(C81,PointsSystem!$A$2:$B$41,2,FALSE())) -> 1
A82: 2 | B82: ECHOPARK (ATLANTA) | C82: 40 | E82: =IF(C82="","",VLOOKUP(C82,PointsSystem!$A$2:$B$41,2,FALSE())) -> 1
A83: 3 | B83: COTA (AUSTIN) | C83: 1 | D83: 45 | E83: =IF(C83="","",VLOOKUP(C83,PointsSystem!$A$2:$B$41,2,FALSE())) -> 55
A84: 3 | B84: COTA (AUSTIN) | C84: 2 | D84: 97 | E84: =IF(C84="","",VLOOKUP(C84,PointsSystem!$A$2:$B$41,2,FALSE())) -> 35
A85: 3 | B85: COTA (AUSTIN) | C85: 3 | D85: 20 | E85: =IF(C85="","",VLOOKUP(C85,PointsSystem!$A$2:$B$41,2,FALSE())) -> 34
A86: 3 | B86: COTA (AUSTIN) | C86: 4 | D86: 54 | E86: =IF(C86="","",VLOOKUP(C86,PointsSystem!$A$2:$B$41,2,FALSE())) -> 33
A87: 3 | B87: COTA (AUSTIN) | C87: 5 | D87: 71 | E87: =IF(C87="","",VLOOKUP(C87,PointsSystem!$A$2:$B$41,2,FALSE())) -> 32
A88: 3 | B88: COTA (AUSTIN) | C88: 6 | D88: 5 | E88: =IF(C88="","",VLOOKUP(C88,PointsSystem!$A$2:$B$41,2,FALSE())) -> 31
A89: 3 | B89: COTA (AUSTIN) | C89: 7 | D89: 9 | E89: =IF(C89="","",VLOOKUP(C89,PointsSystem!$A$2:$B$41,2,FALSE())) -> 30
A90: 3 | B90: COTA (AUSTIN) | C90: 8 | D90: 12 | E90: =IF(C90="","",VLOOKUP(C90,PointsSystem!$A$2:$B$41,2,FALSE())) -> 29
...

Sheet Calc
A1: Race # | B1: Race | C1: Player | D1: Pick Slot | E1: Car # | F1: Finish | G1: Points
A2: 1 | B2: DAYTONA 500 | C2: Pat | D2: 1 | E2: =WeeklyPicks!D2 -> 0 | F2: =IF(E2="","",SUMIFS(RaceResults!$C:$C,RaceResults!$A:$A,A2,RaceResults!$D:$D,E2)) -> 0 | G2: =IF(E2="","",SUMIFS(RaceResults!$E:$E,RaceResults!$A:$A,A2,RaceResults!$D:$D,E2)) -> 0
A3: 1 | B3: DAYTONA 500 | C3: Pat | D3: 2 | E3: =WeeklyPicks!E2 -> 0 | F3: =IF(E3="","",SUMIFS(RaceResults!$C:$C,RaceResults!$A:$A,A3,RaceResults!$D:$D,E3)) -> 0 | G3: =IF(E3="","",SUMIFS(RaceResults!$E:$E,RaceResults!$A:$A,A3,RaceResults!$D:$D,E3)) -> 0
A4: 1 | B4: DAYTONA 500 | C4: Pat | D4: 3 | E4: =WeeklyPicks!F2 -> 0 | F4: =IF(E4="","",SUMIFS(RaceResults!$C:$C,RaceResults!$A:$A,A4,RaceResults!$D:$D,E4)) -> 0 | G4: =IF(E4="","",SUMIFS(RaceResults!$E:$E,RaceResults!$A:$A,A4,RaceResults!$D:$D,E4)) -> 0
A5: 1 | B5: DAYTONA 500 | C5: Meg | D5: 1 | E5: =WeeklyPicks!D3 -> 0 | F5: =IF(E5="","",SUMIFS(RaceResults!$C:$C,RaceResults!$A:$A,A5,RaceResults!$D:$D,E5)) -> 0 | G5: =IF(E5="","",SUMIFS(RaceResults!$E:$E,RaceResults!$A:$A,A5,RaceResults!$D:$D,E5)) -> 0
A6: 1 | B6: DAYTONA 500 | C6: Meg | D6: 2 | E6: =WeeklyPicks!E3 -> 0 | F6: =IF(E6="","",SUMIFS(RaceResults!$C:$C,RaceResults!$A:$A,A6,RaceResults!$D:$D,E6)) -> 0 | G6: =IF(E6="","",SUMIFS(RaceResults!$E:$E,RaceResults!$A:$A,A6,RaceResults!$D:$D,E6)) -> 0
A7: 1 | B7: DAYTONA 500 | C7: Meg | D7: 3 | E7: =WeeklyPicks!F3 -> 0 | F7: =IF(E7="","",SUMIFS(RaceResults!$C:$C,RaceResults!$A:$A,A7,RaceResults!$D:$D,E7)) -> 0 | G7: =IF(E7="","",SUMIFS(RaceResults!$E:$E,RaceResults!$A:$A,A7,RaceResults!$D:$D,E7)) -> 0
A8: 1 | B8: DAYTONA 500 | C8: Darin | D8: 1 | E8: =WeeklyPicks!D4 -> 0 | F8: =IF(E8="","",SUMIFS(RaceResults!$C:$C,RaceResults!$A:$A,A8,RaceResults!$D:$D,E8)) -> 0 | G8: =IF(E8="","",SUMIFS(RaceResults!$E:$E,RaceResults!$A:$A,A8,RaceResults!$D:$D,E8)) -> 0
A9: 1 | B9: DAYTONA 500 | C9: Darin | D9: 2 | E9: =WeeklyPicks!E4 -> 0 | F9: =IF(E9="","",SUMIFS(RaceResults!$C:$C,RaceResults!$A:$A,A9,RaceResults!$D:$D,E9)) -> 0 | G9: =IF(E9="","",SUMIFS(RaceResults!$E:$E,RaceResults!$A:$A,A9,RaceResults!$D:$D,E9)) -> 0
